Workbook
Name _13省当月点对点用户到达数_户81: '[1]#REF'!$A$206
Name _13省当月点对点用户净增数_户82: '[1]#REF'!$A$222
Name _13省点对点用户累计净增数_户83: '[1]#REF'!$A$238
Name AAA: '[1]#REF'!#REF!
Name ABC: '[1]#REF'!$A$302
Name bcd: '[1]#REF'!#REF!
Name efg: '[1]#REF'!#REF!
Name GPRS业务登记用户到达数: '[1]#REF'!$A$643
Name GPRS业务登记用户到达数免费用户: '[1]#REF'!$A$647
Name GPRS业务累计使用量: '[1]#REF'!$A$663
Name GPRS业务使用量: '[1]#REF'!$A$651
Name GPRS业务使用用户到达数: '[1]#REF'!$A$619
Name GPRS业务使用用户到达数免费用户: '[1]#REF'!$A$631
Name HLR总容量: '[1]#REF'!#REF!
Name Internet上网累计使用量: '[1]#REF'!$A$146
Name Internet上网使用量: '[1]#REF'!$A$134
Name Internet上网用户到达数: '[1]#REF'!$A$110
Name Internet上网用户到达数免费用户: '[1]#REF'!$A$122
Name IP充值卡用户数: '[1]#REF'!$A$448
Name IP直通车用户数: '[1]#REF'!$A$443
Name 本年度累计新增市场中移动占有率: '[1]#REF'!$A$77
Name 本年累计IP分钟数情况表: '[1]#REF'!$A$384
Name 本年累计WAP使用量: '[1]#REF'!$A$98
Name 本年累计电信小灵通用户净增数: '[1]#REF'!$A$182
Name 本年累计净增电路总数: '[1]#REF'!#REF!
Name 本年累计联通CDMA用户净增数: '[1]#REF'!$A$106
Name 本年累计联通签约用户净增数: '[1]#REF'!$A$102
Name 本年累计联通预付卡用户净增数: '[1]#REF'!$A$110
Name 本年累计新增用户市场占有率不含预付卡用户: '[1]#REF'!$A$166
Name 本年累计总使用分钟数不含漫游来访的: '[1]#REF'!$A$202
Name 本年累计总通话分钟数分析表: '[1]#REF'!$A$439
Name 本年其他省内签约品牌累计总使用分钟数不含漫游来访的: '[1]#REF'!$A$295
Name 本年其他预付品牌累计总使用分钟数不含漫游来访的: '[1]#REF'!$A$322
Name 本年其它全球通优惠累计总使用分钟数不含漫游来访的: '[1]#REF'!$A$226
Name 本年签约累计总使用分钟数不含漫游来访的: '[1]#REF'!$A$210
Name 本年全球通累计总使用分钟数不含漫游来访的: '[1]#REF'!$A$218
Name 本年全球通预付费累计总使用分钟数不含漫游来访的: '[1]#REF'!$A$313
Name 本年神州行累计总使用分钟数不含漫游来访的: '[1]#REF'!$A$304
Name 本月1860台客服座席数: '[1]#REF'!$A$21
Name 本月1860台客户服务话务员: '[1]#REF'!$A$37
Name 本月1860台人工热线数: '[1]#REF'!$A$52
Name 本月1860台人工热线中投诉电话数: '[1]#REF'!$A$70
Name 本月1860台人工热线中咨询电话数: '[1]#REF'!$A$88
Name 本月DDD分钟数: '[1]#REF'!$A$282
Name 本月IDD分钟数: '[1]#REF'!$A$291
Name 本月IP呼叫DDD: '[1]#REF'!$A$2
Name 本月IP呼叫IDD: '[1]#REF'!$A$86
Name 本月点对点使用量比较表87: '[1]#REF'!$A$733
Name 本月点对点用户数比较表86: '[1]#REF'!$A$723
Name 本月电信小灵通用户到达数: '[1]#REF'!$A$186
Name 本月电信小灵通用户净增数: '[1]#REF'!$A$178
Name 本月非IP呼叫DDD: '[1]#REF'!$A$320
Name 本月非IP呼叫IDD: '[1]#REF'!$A$330
Name 本月高价值用户数比较表65: '[1]#REF'!$A$55
Name 本月净增电路总数: '[1]#REF'!#REF!
Name 本月净增话音信道数量GSM: '[1]#REF'!#REF!
Name 本月净增话音信道数量总数: '[1]#REF'!#REF!
Name 本月净增基站控制器数量GSM: '[1]#REF'!#REF!
Name 本月净增基站数量GSM: '[1]#REF'!#REF!
Name 本月净增基站数量总数: '[1]#REF'!#REF!

Sheet Sheet1
B2: 后续要考虑的事项：
B3: 1、修改后的总表1、2，能不能加一列，展示每个指标的折现图，历年or历月变化情况
B4: 2、分市场表里增加存量保有情况。
B10: 1、第一页和第四页合并，第一部分就是财务状态，第二部分就是业务运营，就是业务部、基站；第三部分份额啥的。两增长和4提升和上市相关的，可以放里面。
B11: 2、开通轻量化（RedCap）功能5G基站是5G基站开通这个功能，只有这一个功能，还是说基于现有基站，只需要进行软件升级or改造，就能开通这功能。
B12: 3、主要产品业务情况表。能不能吧“8+5”的都放进来，补充下政企市场产品。
B13: 4、个人市场分省主要产品表。能不能挑一挑重点指标，合成一张表。
B14: 5、主要产品效益情况表，问下丛鑫CHBN是不是就是通信服务收入全量；（基础）能不能去掉；除了主要产品，能不能只展示重点产品的情况，比如政企市场指标太多了。
B15: 6、主表（分省也可以看下）标题的括号，都放在标题最后
B20: 回答
B21: 1、已改
B22: 2、是基于现有5G基站进行升级、开通RedCap功能的基站。
... B28: 8、两增长、四提升方面的指标。两增长即收入和利润增长，现有月报已有展示；四提升，董事长报告书只是提了概念，没有列出具体对应的指标。科创能力提升方面，问了预算处，国资委在2024年预算报表中增加了一张《核心竞争力和核心功能情况表》里面有科技指标（包含研发经费投入、研发经费投入强度、科技收入、专利数、论文数、国家级创新平台数量等）、效率指标、人才指标等，目前口径没定，技术部正在牵头研究口径。研发经费投入强度已经在月报中展示，建议不再增加其他指标。

Sheet 目录1
A1: 目 录
B2: 一、高质量发展指标情况表 *………………………………………………………………………………………………………………… | I2: 1
B3: 一、上市公司主要情况表………………………………………………………………………………………………………………… | I3: （1~16）
B4: 主要经营情况表（1/16）……………………………………………………………………………… | I4: 1
B5: CHBN收入情况表（2/16）………………………………………………………………………………………… | I5: 2
B6: 连接+算力+能力情况表（3/16）………………………………………………………………………………………………… | I6: 3
B7: 5G业务情况表（4/16）………………………………………………………………………………………………… | I7: 4
B8: 移动云业务情况表（5/16）……………………………………………………………………………………………… | I8: 5
B9: 主要产品运营情况表（6/16）……………………………………………………………………………………………… | I9: 6
B10: 个人市场整体情况表（7/16）…………………………………………………………………………… | I10: 7
B11: 家庭市场整体情况表（8/16）………………………………………………………………………………………………………………………… | I11: 8
B12: 政企市场整体情况表（9/16）………………………………………………………………………………………………………………………… | I12: 9
B13: 网络能力与投资情况表（10/16） ………………………………………………………………………………………………………………… | I13: 10
B14: 营运收入情况表（11/16）………………………………………………………………………………………………… | I14: 11
B15: 营运支出情况表（12/16）…………………………………………………………………………………… | I15: 12
... B19: 电信行业主要指标情况表（续）（16/16）………………………………………………………………………… | I19: 16
B20: 二、上市公司各省主要情况表…………………………………………………………………………… | I20: (17~52)
B21: 收入和利润情况表（1/36)……………………………………………………………………… | I21: 17
B22: 数字化转型收入和支出情况表（2/36)…………………………………………………………………………………………………………………………… | I22: 18
B23: “CHBN”收入情况表（3/36)………………………………………………………………………………………………………………… | I23: 19
B24: 分市场收入驱动因素情况表（4/36)……………………………………………………………… | I24: 20
B25: 收入与行业发展、宏观经济对比情况表（5/36)………………………………………………………………………………………………………………… | I25: 21
B26: 总连接情况表（6/36)………………………………………………………………… | I26: 22
B27: 移动电话客户情况表（7/36)……………………………………………………………… | I27: 23
B28: 有线宽带业务情况表（8/36)………………………………………………………………………………………………………………… | I28: 24
B29: 千兆有线宽带业务情况表（9/36)………………………………………………………………………………………………………………… | I29: 25
B30: 个人市场-5G套餐客户情况表（10/36)…………………………………………………………………………………………………………………………… | I30: 26
B31: 个人市场-5G网络客户情况表（11/36)…………………………………………………………………………………………………………………………… | I31: 27
B32: 个人市场-5G机套网客户情况表（12/36)…………………………………………………………………………………………………………………………… | I32: 28
B34: *为支撑高质量发展，统计月报围绕考核管控、经营目标等重点梳理指标，新增《高质量发展指标情况表》

Sheet 目录2
B1: 个人市场-个人上网业务情况表（13/36)…………………………………………………………………………………………………………………………… | I1: 29
B2: 个人市场-手机上网业务情况表（14/36)…………………………………………………………………………………………………………………………… | I2: 30
B3: 个人市场-携号转网情况表（15/36)…………………………………………………………………………………………………………………………… | I3: 31
B4: 个人市场-重点产品情况表（16/36)……………………………………………………………… | I4: 32
B5: 个人市场-重点产品情况表（续）（17/36)……………………………………………………………… | I5: 33
B6: 家庭市场-家庭宽带业务情况表（18/36)……………………………………………………………… | I6: 34
B7: 家庭市场-家庭宽带业务情况表（续）（19/36)…………………………………………………… | I7: 35
B8: 家庭市场-移动高清业务情况表（20/36)……………………………………………………………… | I8: 36
B9: 家庭市场-重点产品情况表（21/36)……………………………………………………………… | I9: 37
B10: 政企市场-客户和DICT收入情况表（22/36)………………………………………………………………………… | I10: 38
B11: 政企市场-行业份额情况表（23/36)……………………………………………………………… | I11: 39
B12: 政企市场-专线业务情况表（24/36)…………………………………………………………………………… | I12: 40
... B24: 重点地市业务数据表（续）（36/36)………………………………………………………………………………………………………………… | I24: 52
B25: 三、专业公司主要情况表…………………………………………………………………………………. | I25: （53~62）
B26: 香港公司主要情况表……………………………………………………………………………………… | I26: 53
B27: 辛姆巴科公司主要情况表……………………………………………………………………………………… | I27: 54
B28: 国际公司主要情况表……………………………………………………………………………………… | I28: 55
B29: 财务公司、终端公司主要情况表……………………………………………………………………………………… | I29: 56
B30: 中移铁通公司主要情况表……………………………………………………………………………………… | I30: 57
B31: 集成公司、在线营销服务中心、物联网公司主要情况表……………………………………………………………………………………… | I31: 58
B32: 金科公司、信息技术中心主要情况表……………………………………………………………………………………… | I32: 59
B33: 专业公司、事业部及直属单位主要财务指标表……………………………………………………………………………………… | I33: 60
B34: 四、集团公司人员和薪酬情况表……………………………………………………………………………………… | I34: 61
B35: 五、集团公司主要情况表……………………………………………………………………… | I35: 62

Sheet 主要经营情况表
A1: 上市公司主要经营情况表（1/16）
A2: 45323
A3: 指标 | B3: 单位 | C3: 本月实际 | D3: 比上月± | E3: 比上年同期± | F3: 本年累计 | G3: 比上年同期±
A4: 一、经营业绩
A5: （一）营运收入 | B5: 亿元 | C5: 906.01272 | D5: -0.071866415 | E5: 0.027292438 | F5: 1882.179 | G5: 0.032259278
A6: 1.通信服务收入 | B6: 亿元 | C6: 776.99523 | D6: -0.032483166 | E6: 0.020870014 | F6: 1580.0771 | G6: 0.020617651
A7: 其中：数字化转型收入 | B7: 亿元 | C7: 245.3963 | D7: -0.076775135 | E7: 0.1336611 | F7: 511.19969 | G7: 0.11892124
A8: 其中：算力网络收入 | B8: 亿元 | C8: 138.15411 | D8: -0.1537844 | E8: 0.1140614 | F8: 301.41523 | G8: 0.11015701
A9: 2.销售产品收入及其他 | B9: 亿元 | C9: 129.01749 | D9: -0.2545979 | E9: 0.067746916 | F9: 302.10191 | G9: 0.09774985
A10: （二）营运支出 | B10: 亿元 | C10: 736.23642 | D10: -0.059298287 | E10: 0.075596822 | F10: 1518.8824 | G10: 0.06320185
A11: （三）营运利润 | B11: 亿元 | C11: 169.7763 | D11: -0.12269516 | E11: -0.14016111 | F11: 363.29661 | G11: -0.079716739
A12: （四）归属于母公司所有者的净利润 | B12: 亿元 | C12: 151.97367 | D12: -0.032629667 | E12: -0.10828462 | F12: 309.07345 | G12: -0.081225066
A13: 净利润率 | B13: % | C13: 0.167739 | D13: 0.680353 | E13: -2.550316 | F13: 0.16421045 | G13: -2.0282785
A14: （五）EBITDA | B14: 亿元 | C14: 346.17503 | D14: -0.065299361 | E14: -0.068260325 | F14: 716.53429 | G14: -0.029586494
A15: EBITDA margin | B15: % | C15: 0.38208629 | D15: 0.26844759 | E15: -3.9184121 | F15: 0.38069402 | G15: -2.4262147
A16: （六）资产总额 | B16: 亿元 | C16: - | D16: - | E16: - | F16: 19652.564 | G16: 0.019178387
A17: 其中：货币资金 | B17: 亿元 | C17: - | D17: - | E17: - | F17: 2485.6838 | G17: -0.08163684
A18: （七）负债总额 | B18: 亿元 | C18: - | D18: - | E18: - | F18: 6222.4031 | G18: -0.015659751
A19: 资产负债率 | B19: % | C19: - | D19: - | E19: - | F19: 0.31662041 | G19: -1.1205948
A20: （八）经营净现金流 | B20: 亿元 | C20: 254.97438 | D20: 11.990689 | E20: -0.099541257 | F20: 274.60186 | G20: -0.43434707
A21: （九）自由现金流 | B21: 亿元 | C21: 215.0144 | D21: - | E21: 0.068775527 | F21: 140.40726 | G21: -0.57086886
A22: 二、业务运营
A23: （一）移动计费总时长 | B23: 亿分钟 | C23: 1989.0403 | D23: -0.14217867 | E23: -0.11485198 | F23: 4307.7519 | G23: -0.06763202
A24: （二）短彩信计费量 | B24: 亿条 | C24: 727.47341 | D24: -0.1185024 | E24: -0.054926271 | F24: 1552.7433 | G24: 0.0039086597
A25: 其中：集团短信计费量 | B25: 亿条 | C25: 617.94295 | D25: -0.11592465 | E25: 0.023788554 | F25: 1316.9138 | G25: 0.087168248
A26: （三）移动数据流量 | B26: 亿MB | C26: 121963.58 | D26: -0.12466615 | E26: 0.018990687 | F26: 261297.37 | G26: 0.069909991
A27: 其中：手机上网流量 | B27: 亿MB | C27: 119128.07 | D27: -0.12532187 | E27: 0.0071415762 | F27: 255324.53 | G27: 0.057741259
A28: （四）基站数 | B28: 万个 | C28: - | D28: - | E28: - | F28: 667.1712 | G28: 0.098158941
A29: （五）资本开支 | B29: 亿元 | C29: 39.959988 | D29: -0.57595212 | E29: -0.51257777 | F29: 134.1946 | G29: -0.15211787
A30: 资本开支占通信服务收入比重 | B30: % | C30: 0.051428872 | D30: -6.5912356 | E30: -5.6285118 | F30: 0.084929147 | G30: -1.7302264
A31: 三、竞争态势
A32: （一）行业通信服务收入增幅 | B32: % | C32: - | D32: - | E32: - | F32: 0.0426 | G32: -3.15
A33: 公司通信服务收入增幅与行业收入增幅差 | B33: % | C33: - | D33: - | E33: - | F33: -1.4103526 | G33: -
A34: （二）通信服务收入份额 | B34: % | C34: - | D34: - | E34: - | F34: 0.52275603 | G34: -0.87892477
A35: （三）政企市场收入份额 | B35: % | C35: - | D35: - | E35: - | F35: 0.40367639 | G35: -0.37351247
A36: （四）移动电话客户份额 | B36: % | C36: - | D36: - | E36: - | F36: 0.5702233 | G36: -0.52234362
A37: 移动电话客户净增份额 | B37: % | C37: 0.21855808 | D37: -4.7789189 | E37: 4.8684117 | F37: 0.21855808 | G37: 4.8684117
A38: （五）有线宽带客户份额 | B38: % | C38: - | D38: - | E38: - | F38: 0.4690676 | G38: 0.66448778
A39: 有线宽带客户净增份额 | B39: % | C39: 0.54382703 | D39: 55.248469 | E39: -6.7832051 | F39: 0.54382703 | G39: -6.7832051
A40: （六）千兆有线宽带客户份额 | B40: % | C40: - | D40: - | E40: - | F40: 0.50643044 | G40: 6.7337223
...

Sheet 主要财务情况表
A1: 上市公司主要财务情况表（1/17） | L1: 删除部分指标，其余的放在表一上市公司主要经营情况表
A2: 2024年
A3: 指标 | B3: 单位 | C3: 本月实际 | D3: 比上月± | E3: 比上年同期± | F3: 本年累计 | G3: 比上年同期± | H3: 占收入比重
A4: 一、营运收入 | B4: 亿元
A5: （一）通信服务收入 | B5: 亿元
A6: 其中：个人市场收入（C） | B6: 亿元
A7: 家庭市场收入（H） | B7: 亿元
A8: 政企市场收入（B） | B8: 亿元
A9: 新兴市场收入（N） | B9: 亿元
A10: 其中：数字化转型收入 | B10: 亿元
A11: 其中：算力网络收入 | B11: 亿元
A12: （二）销售产品收入及其他 | B12: 亿元
A13: 二、营运支出 | B13: 亿元
A14: 其中：成本费用总额 | B14: 亿元
A15: 三、营运利润 | B15: 亿元
... A29: 资产负债率 | B29: %
A30: 九、现金流量
A31: 1.经营净现金流 | B31: 亿元
A32: 2.自由现金流 | B32: 亿元
A33: 注：1.数字化转型收入包括个人市场新业务（移动云盘等）收入，家庭市场智慧家庭增值业务收入，政企市场DICT收入、物联网收入、专线收入，以及新兴市场收入
A34: 2.算力网络收入包括个人市场移动云盘（个人）收入，家庭市场移动云盘（家庭）收入、家庭安防收入，政企市场DICT收入、物联网功能费，
A35: 新兴市场内容媒体和国际算力网络业务收入
A36: 3.成本费用总额=营运支出-销售产品成本+融资成本
A37: 1

Sheet CHBN收入报表
A1: CHBN收入情况表（2/16）
A2: =主要经营情况表!A2 -> 45323
A3: 指标 | B3: 单位 | C3: 本月实际 | D3: 比上月± | E3: 比上年同期± | F3: 本年累计 | G3: 比上年同期± | H3: 占通信服务收入比
A4: 通信服务收入 | B4: 亿元 | C4: 776.99523 | D4: -0.0325 | E4: 0.020870014 | F4: 1580.0771 | G4: 0.020617651 | H4: 1
A5: 一、个人市场收入（C） | B5: 亿元 | C5: 430.86084 | D5: -0.0076985941 | E5: -0.021391716 | F5: 865.06444 | G5: -0.025469581 | H5: 0.54748242
A6: 1.个人语音 | B6: 亿元 | C6: 55.536706 | D6: -0.078573048 | E6: -0.075521914 | F6: 115.80921 | G6: -0.050442431 | H6: 0.07329339
A7: 2.个人短彩信 | B7: 亿元 | C7: 2.7829826 | D7: 0.29299423 | E7: 0.27920135 | F7: 4.9353375 | G7: 0.12033366 | H7: 0.0031234789
A8: 3.个人无线上网 | B8: 亿元 | C8: 339.01571 | D8: 0.0038748478 | E8: -0.035282031 | F8: 676.72286 | G8: -0.043243615 | H8: 0.42828471
A9: 4.个人新业务 | B9: 亿元 | C9: 28.059439 | D9: 0.14110727 | E9: 0.59879778 | F9: 52.649097 | G9: 0.45282884 | H9: 0.033320588
A10: 5.其他 | B10: 亿元 | C10: 5.4659993 | D10: -0.42353537 | E10: -0.39704593 | F10: 14.947933 | G10: -0.1582484 | H10: 0.0094602553
A11: 二、家庭市场收入（H） | B11: 亿元 | C11: 115.81369 | D11: -0.0094863415 | E11: 0.075159274 | F11: 232.73656 | G11: 0.080947402 | H11: 0.14729443
A12: 1.家庭语音 | B12: 亿元 | C12: 0.89124119 | D12: 0.001446539 | E12: -0.15696816 | F12: 1.781195 | G12: -0.16731925 | H12: 0.0011272836
A13: 2.家庭宽带 | B13: 亿元 | C13: 83.690915 | D13: -0.017574447 | E13: 0.085957618 | F13: 168.87896 | G13: 0.09504403 | H13: 0.1068802
A14: 3.智慧家庭增值业务 | B14: 亿元 | C14: 31.139832 | D14: 0.012895116 | E14: 0.058271434 | F14: 61.883225 | G14: 0.055684035 | H14: 0.039164687
A15: 4.其他 | B15: 亿元 | C15: 0.091705591 | D15: -0.096229047 | E15: -0.45695791 | F15: 0.19317554 | G15: -0.41210873 | H15: 0.00012225703
... A32: （四）资本运作并表收入 | B32: 亿元 | C32: 0 | D32: 0 | E32: 0 | F32: 0 | G32: 0 | H32: 0
A33: 注：1.个人市场、家庭市场、政企市场、新兴市场为互斥关系，合计等于财务报表《香港口径损益表》中的“通信服务收入”
A34: 2.网间结算收入按照各市场的语音、短彩信收入权重进行分摊
A35: 3.物联网流量收入属于政企市场无线上网收入，不属于个人市场收入
A36: 4.个人市场收入包含政企客户代成员用户付费收入
A37: 5.本年截至目前，家庭类内容媒体、资本运作两项暂无收入，后续将逐步随着业务实际发展状况展示相关数据
A38: =主要经营情况表!A47+1 -> 2

Sheet 连接+算力+能力情况表
A1: 连接+算力+能力情况表（3/16）
A2: =主要经营情况表!A2 -> 45323
A3: 指标 | B3: 单位 | C3: 本月实际 | D3: 比上月± | E3: 比上年同期± | F3: 本年累计 | G3: 比上年同期±
A4: 一、连接
A5: （一）总连接数 | B5: 万 | C5: - | D5: - | E5: - | F5: 337911.95 | G5: 0.12649179
A6: 1.网络连接数 | B6: 万户 | C6: - | D6: - | E6: - | F6: 260734.88 | G6: 0.11584023
A7: 其中：移动电话客户数 | B7: 万户 | C7: - | D7: - | E7: - | F7: 99106.556 | G7: 0.012688813
A8: —5G网络客户数 | B8: 万户 | C8: - | D8: - | E8: - | F8: 47473.219 | G8: 0.37692118
A9: 有线宽带客户数 | B9: 万户 | C9: - | D9: - | E9: - | F9: 30237.259 | G9: 0.089077154
A10: —家庭宽带客户数 | B10: 万户 | C10: - | D10: - | E10: - | F10: 26711.157 | G10: 0.076203392
A11: 物联网卡客户数 | B11: 万户 | C11: - | D11: - | E11: - | F11: 131391.07 | G11: 0.21615627
A12: 2.设备连接数 | B12: 万 | C12: - | D12: - | E12: - | F12: 77177.069 | G12: 0.16403112
A13: 其中：家庭设备数 | B13: 万 | C13: - | D13: - | E13: - | F13: 51079.746 | G13: 0.20394143
A14: 行业设备数 | B14: 万 | C14: - | D14: - | E14: - | F14: 26097.323 | G14: 0.093106817
A15: （二）净增总连接数 | B15: 万 | C15: 1029.2042 | D15: -0.28445118 | E15: -0.72520325 | F15: 2467.5466 | G15: -0.58631736
A16: 1.净增网络连接数 | B16: 万户 | C16: 42.233 | D16: -0.77229705 | E16: -0.98464431 | F16: 227.7071 | G16: -0.91676291
A17: 其中：净增移动电话客户数 | B17: 万户 | C17: -51.0601 | D17: -1.8855484 | E17: -1.1626996 | F17: 6.5992 | G17: -0.98187754
A18: —净增5G网络客户数 | B18: 万户 | C18: 828.7119 | D18: 4.0737722 | E18: 0.023480431 | F18: 992.0444 | G18: -0.43682949
A19: 净增有线宽带客户数 | B19: 万户 | C19: 151.3206 | D19: -0.42107645 | E19: -0.4860898 | F19: 412.7033 | G19: -0.24590693
A20: 净增物联网卡客户数 | B20: 万户 | C20: -58.0275 | D20: - | E20: -1.0270899 | F20: -191.5954 | G20: -1.1050289
A21: 2.净增设备连接数 | B21: 万 | C21: 986.9712 | D21: -0.21223069 | E21: -0.0080821055 | F21: 2239.8395 | G21: -0.30637631
A22: 其中：净增家庭设备数 | B22: 万 | C22: 918.8342 | D22: -0.033112354 | E22: 0.17189974 | F22: 1869.1351 | G22: -0.37654122
A23: 净增行业设备数 | B23: 万 | C23: 68.137 | D23: -0.77480389 | E23: -0.67701108 | F23: 370.7044 | G23: 0.60355711
A24: 二、算力
A25: 1. 服务器算力规模（用FP32精度计算） | B25: EFLOPS | C25: - | D25: - | E25: - | F25: 11 | G25: 0.375
A26: 其中：智算规模（用FP32精度计算） | B26: EFLOPS | C26: - | D26: - | E26: - | F26: 3 | G26: -
A27: 2.智算规模（用FP16精度计算） | B27: EFLOPS | C27: - | D27: - | E27: - | F27: 10 | G27: -
A28: 3. 数据中心机架数（含自用、合作） | B28: 万个 | C28: - | D28: - | E28: - | F28: 134 | G28: 0.072
A29: 数据中心平均PUE值 | B29: - | C29: - | D29: - | E29: - | F29: 1.32 | G29: -0.029411765
A30: 4.自有可装机架数 | B30: 万个 | C30: - | D30: - | E30: - | F30: 122.5 | G30: -
A31: 三、能力
A32: 1. 汇聚中台能力数量 | B32: 项 | C32: - | D32: - | E32: - | F32: 1036 | G32: 0.16143498
A33: 2. 智慧中台能力调用量 | B33: 亿次 | C33: 524.82 | D33: -0.05507643 | E33: 0.79948568 | F33: 524.82 | G33: 0.79948568
A34: 注：1.总连接数=网络连接数+设备连接数。其中，网络连接数=移动电话客户数+有线宽带客户数+物联网卡客户数，设备连接数=家庭设备数
A35: +行业设备数
A36: 2.家庭设备数=移动高清设备数+智能组网、语音遥控器、智能安防、智能音箱、智能电视等智家设备数
A37: 3.行业设备数=OneNET平台连接设备数+千里眼连接设备数+和商务TV设备数+云视讯硬终端设备数
A38: 4.算力规模、数据中心机架数、自有可装机架数按季度统计，为截至2023年12月数据；数据中心平均PUE值按季度统计，为2023年全年的平均值
A39: 5.自有可装机架数是指由我公司投资建设，产权、资产完全归我公司所有的数据中心和通信枢纽机房的全部可装机架
A40: 6.汇聚中台能力数量、智慧中台能力调用量为上月值
...

Sheet 主要业务指标
A1: 主要运营情况表（4/17） | I1: 删除部分指标，其余的放在表一上市公司主要经营情况表
A2: =主要经营情况表!A2 -> 45323
A3: 指标 | B3: 单位 | C3: 本月实际 | D3: 比上月± | E3: 比上年同期± | F3: 本年累计 | G3: 比上年同期±
A4: 一、业务量
A5: 1. 移动计费总时长 | B5: 亿分钟
A6: 2. 短彩信计费量 | B6: 亿条
A7: 3. 移动数据流量 | B7: 亿MB
A8: 其中：物联网流量 | B8: 亿MB | I8: 挪到政企表
A9: 二、基站与投资
A10: 1. 基站数 | B10: 万个
A11: —5G基站数 | B11: 万个 | I11: 删除，5G表中有
A12: 2. 净增基站数 | B12: 万个 | I12: 删除，能力表中有
A13: —净增5G基站数 | B13: 万个 | I13: 删除，5G表中有
A14: 3. 资本开支 | B14: 亿元
A15: —5G资本开支 | B15: 亿元 | I15: 删除，5G表中有
A16: 4. 资本开支占通信服务收入比重 | B16: %
A17: 三、资费
A18: 1. 每分钟语音业务收入 | B18: 元/分钟 | I18: 挪到个人市场表
A19: 2. 手机上网流量资费 | B19: 元/GB | I19: 删除，个人市场表中有
A20: 四、市场份额
A21: 1. 行业通信服务收入增幅 | B21: %
A22: 2. 通信服务收入增幅与行业收入增幅差 | B22: %
A23: 3. 通信服务收入份额 | B23: %
A24: 4. 移动电话客户份额 | B24: %
A25: —5G网络客户份额 | B25: % | I25: 删除，挪到5G表中
A26: 5. 移动电话客户净增份额 | B26: %
A27: —5G网络客户净增份额 | B27: % | I27: 删除，挪到5G表中
A28: 6.有线宽带客户份额 | B28: %
A29: —千兆有线宽带客户份额 | B29: %
A30: 7.有线宽带客户净增份额 | B30: %
A31: —千兆有线宽带客户净增份额 | B31: %
A32: 注：1.基站数=GSM基站+TD-LTE基站+LTE FDD+5G基站+NB-IoT基站 | I32: 删除3G基站
A33: 自3月起，5G室内基站改按行业通用口径统计（一次性调整到位，往期数据不追溯） | I33: 删除
A34: 2.市场份额根据工业和信息化部公布数据计算得出，为上月值
A35: 4

Sheet 5G业务指标表
A1: 5G业务情况表（4/16）
A2: =主要经营情况表!A2 -> 45323
A3: 指标 | B3: 单位 | C3: 本月实际 | D3: 比上月± | E3: 比上年同期± | F3: 本年累计 | G3: 比上年同期±
A4: 一、客户发展
A5: （一）2C市场
A6: 1.5G套餐客户数 | B6: 万户 | C6: - | D6: - | E6: - | F6: 80078.506 | G6: 0.25292479
A7: 5G终端客户数 | B7: 万户 | C7: - | D7: - | E7: - | F7: 57651.448 | G7: 0.28992532
A8: 5G网络客户数 | B8: 万户 | C8: - | D8: - | E8: - | F8: 47473.219 | G8: 0.37692118
A9: —700M 5G网络客户数 | B9: 万户 | C9: - | D9: - | E9: - | F9: 31898.341 | G9: 0.62411693
A10: 5G机套网客户数 | B10: 万户 | C10: - | D10: - | E10: - | F10: 39588.919 | G10: 0.50178712
A11: 2.净增5G套餐客户数 | B11: 万户 | C11: 1127.3208 | D11: - | E11: -0.32328429 | F11: 628.2272 | G11: -0.74998266
A12: 净增5G终端客户数 | B12: 万户 | C12: 1102.0972 | D12: 0.57840486 | E12: -0.019705212 | F12: 1800.332 | G12: -0.26704169
A13: 净增5G网络客户数 | B13: 万户 | C13: 828.7119 | D13: 4.0737722 | E13: 0.023480431 | F13: 992.0444 | G13: -0.43682949
A14: 净增5G机套网客户数 | B14: 万户 | C14: 1172.2347 | D14: - | E14: 0.29178572 | F14: 1152.641 | G14: -0.38283077
A15: （二）2B市场
A16: 1.5G物联卡客户数 | B16: 万户 | C16: - | D16: - | E16: - | F16: 1187.8419 | G16: 2.7451529
A17: 净增5G物联卡客户数 | B17: 万户 | C17: 69.0291 | D17: 2.1041893 | E17: 0.78802682 | F17: 91.2665 | G17: 0.3288348
A18: 二、发展质量
A19: （一）2C市场
A20: 1.5G套餐客户渗透率 | B20: % | C20: - | D20: - | E20: - | F20: 0.80800412 | G20: 15.492683
A21: 5G套餐客户出账ARPU | B21: 元/户·月 | C21: 67.193834 | D21: 0.042982979 | E21: -0.12925551 | F21: 65.757351 | G21: -0.11420325
A22: 5G套餐客户DOU | B22: GB/户·月 | C22: 13.662185 | D22: -0.06820897 | E22: -0.15185835 | F22: 14.171997 | G22: -0.098956884
A23: 2.5G网络客户渗透率 | B23: % | C23: - | D23: - | E23: - | F23: 0.4790119 | G23: 12.671142
A24: 5G网络客户出账ARPU | B24: 元/户·月 | C24: 79.150445 | D24: 0.044406511 | E24: -0.083337789 | F24: 77.403732 | G24: -0.06665479
A25: 5G网络客户DOU | B25: GB/户·月 | C25: 18.647272 | D25: -0.079598286 | E25: -0.17515116 | F25: 19.467623 | G25: -0.10807211
A26: 5G网络流量占比 | B26: % | C26: 0.56988297 | D26: -0.84824823 | E26: 11.737505 | F26: 0.5744082 | G26: 14.560161
A27: 5G流量中700M流量占比 | B27: % | C27: 0.24888835 | D27: 5.459086 | E27: 9.5089705 | F27: 0.21956458 | G27: 5.037341
A28: 3.5G机套网匹配率 | B28: % | C28: - | D28: - | E28: - | F28: 0.68969711 | G28: 9.7685409
A29: 5G机套网客户出账ARPU | B29: 元/户·月 | C29: 85.582722 | D29: 0.03956516 | E29: -0.1095506 | F29: 83.882244 | G29: -0.091655203
A30: 5G机套网客户DOU | B30: GB/户·月 | C30: 20.003784 | D30: -0.077051726 | E30: -0.15940417 | F30: 20.843632 | G30: -0.097657897
A31: （二）2B市场
A32: 1.5G专网收入 | B32: 亿元 | C32: 4.9668429 | D32: -0.35520769 | E32: 0.41148558 | F32: 12.669855 | G32: 0.58498971
A33: 三、网络能力及投资
A34: 1.5G基站数 | B34: 万个 | C34: 1.5105 | D34: -0.66254859 | E34: -0.50368009 | F34: 200.5492 | G34: 0.51223897
A35: 其中：5G 700MHz基站数 | B35: 万个 | C35: 0.5874 | D35: -0.57245797 | E35: -0.27651189 | F35: 63.9137 | G35: 0.29476149
A36: 其中：开通轻量化（RedCap）功能5G基站数 | B36: 万个 | C36: -5.0336 | D36: - | E36: - | F36: 14.1953 | G36: -
A37: 2.5G载频数 | B37: 万个 | C37: 3.5599 | D37: -0.43595716 | E37: -0.54064621 | F37: 462.307 | G37: 0.26193297
A38: —5G 700MHz载频数 | B38: 万个 | C38: 1.5017 | D38: -0.45651623 | E38: -0.20884042 | F38: 185.407 | G38: 0.28302594
A39: 3.5G资本开支 | B39: 亿元 | C39: 19.662287 | D39: -0.68919274 | E39: -0.61069446 | F39: 82.924279 | G39: -0.11627192
A40: 四、网络情况
...

Sheet 移动云业务情况表
A1: 移动云业务情况表（5/16）
A2: =主要经营情况表!A2 -> 45323
A3: 指标 | B3: 单位 | C3: 本月实际 | D3: 比上月± | E3: 比上年同期± | F3: 本年累计 | G3: 比上年同期±
A4: 一、收入
A5: 移动云业务收入 | B5: 亿元 | C5: 75.474154 | D5: -0.17010632 | E5: 0.086041811 | F5: 166.41852 | G5: 0.12718889
A6: 1.行业云收入 | B6: 亿元 | C6: 63.404992 | D6: -0.19070301 | E6: 0.050326351 | F6: 141.75076 | G6: 0.092528939
A7: 其中：公有云收入 | B7: 亿元 | C7: 40.028179 | D7: -0.057058962 | E7: 0.0032611894 | F7: 82.478531 | G7: -0.00034576663
A8: 其中：云标准化产品收入 | B8: 亿元 | C8: 15.467431 | D8: -0.094402732 | E8: -0.21733815 | F8: 32.547244 | G8: -0.15166493
A9: 云网收入 | B9: 亿元 | C9: 14.765212 | D9: 0.034099881 | E9: 0.051929349 | F9: 29.043534 | G9: 0.0093178408
A10: 云数收入 | B10: 亿元 | C10: 2.4076756 | D10: -0.25251465 | E10: -0.03112682 | F10: 5.6287095 | G10: 0.24839054
A11: 云智收入 | B11: 亿元 | C11: 0.20164676 | D11: -0.44662806 | E11: 0.48334674 | F11: 0.5660432 | G11: 1.2477611
A12: 云边收入 | B12: 亿元 | C12: 5.0444998 | D12: 0.1391988 | E12: 0.93919894 | F12: 9.4726117 | G12: 0.73913995
A13: 云通信收入 | B13: 亿元 | C13: 2.1417136 | D13: -0.30433911 | E13: 1.4425028 | F13: 5.2203882 | G13: 0.012035584
A14: 私有云收入 | B14: 亿元 | C14: 23.376813 | D14: -0.34875209 | E14: 0.14206605 | F14: 59.272226 | G14: 0.25474455
A15: 其中：云定制化项目收入 | B15: 亿元 | C15: 20.879335 | D15: -0.35493698 | E15: 0.12580765 | F15: 53.247235 | G15: 0.22862169
A16: 云数-ICT大数据收入 | B16: 亿元 | C16: 2.4974775 | D16: -0.29200055 | E16: 0.29888534 | F16: 6.0249908 | G16: 0.54507512
... A24: 云VR\云AR | B24: 亿元 | C24: 0.023246626 | D24: 0.1275119 | E24: -0.49874198 | F24: 0.043864258 | G24: -0.44342528
A25: 二、业务发展
A26: 1.公有云资源池主机数量 | B26: 台 | C26: 7027 | D26: -0.18555865 | E26: -0.1847082 | F26: 234065 | G26: 0.30492109
A27: 2.公有云资源池资源总量 | B27: vCPU | C27: 29186.2 | D27: -0.95085406 | E27: - | F27: 8475447.4 | G27: 0.45797092
A28: 其中：公有云资源池已售资源数量 | B28: vCPU | C28: -23042.17 | D28: - | E28: -1.0960863 | F28: 3841752.4 | G28: 0.37065391
A29: 3.公有云资源池存储容量 | B29: TB | C29: 558119.19 | D29: 0.87018963 | E29: 20.30722 | F29: 5684851.2 | G29: 1.2926768
A30: 其中：公有云资源池已售存储容量 | B30: TB | C30: 267928.85 | D30: 1.5232638 | E30: 2.0065307 | F30: 1874084 | G30: 1.154585
A31: 5.公有云已售带宽 | B31: G | C31: 1166.95 | D31: -0.7849827 | E31: 2.8228068 | F31: 36105.89 | G31: 0.86459997
A32: 三、市场份额
A33: 行业云收入份额 | B33: % | C33: - | D33: - | E33: - | F33: 0.45885283 | G33: 0.46657944
A34: 注：1.收入指标取自管理会计收入报表
A35: 2.移动云业务收入=行业云收入+移动云盘收入+其他云收入
A36: 3.行业云收入=公有云+私有云收入，其中公有云收入=云标准化产品收入[IaaS+PaaS（含9one标准产品、云视讯）+SaaS收入]+云网+云数+云智+云边+云通信收入;
A37: 私有云收入=云定制化项目收入（含ICT9one收入）+云边_局域边缘云收入+云数_ICT大数据收入
A38: 4.云网收入=云专线业务收入+云互联业务收入+IDC入云带宽收入
A39: 5.云数收入=公有云云数收入（乾坤大数据业务收入+其他大数据业务收入）+私有云云数收入（ICT大数据收入）
A40: 6.云边收入=公有云云边收入（CDN+专属云业务收入+广域边缘云业务收入）+私有云云边收入（局域边缘云业务收入）
A41: 7.云通信收入=云MAS收入+云IoT收入+能力开放收入
A42: 8.云定制化项目收入=移动方投资定制化项目收入+ICT服务中云计算收入+ICT服务中9one收入
A43: 9.市场份额取自政企事业部，为上月值
A44: ='5G业务指标表'!A50+1 -> 5

Sheet 主要产品业务情况表
A1: 主要产品运营情况表（6/16）
A2: =主要经营情况表!A2 -> 45323
A3: 产品名称 | B3: 指标 | C3: 单位 | D3: 数值 | E3: 比上月± | F3: 比上年同期±
A4: 一、C+N (个人市场与新兴市场）
A5: 权益 | B5: 融合客户到达数 | C5: 万户 | D5: 31666.01 | E5: -0.043791243 | F5: 0.066896829
A6: 咪咕视频 | B6: 全场景月活用户数 | C6: 万户 | D6: 36422.702 | E6: -0.046813897 | F6: 0.062459597
B7: 会员到达数 | C7: 万户 | D7: 24717.566 | E7: -0.011224986 | F7: 0.10922717
B8: 手机APP月活用户数 | C8: 万户 | D8: 9332.8652 | E8: 0.024802118 | F8: -
A9: 视频彩铃 | B9: 订购用户数 | C9: 万户 | D9: 40589.219 | E9: 0.004713509 | F9: 0.13165364
B10: 会员用户数 | C10: 万户 | D10: 16378.542 | E10: -0.0026504336 | F10: -
B11: 行为月活用户数 | C11: 万户 | D11: 8421.0632 | E11: 0.20730455 | F11: -
A12: 移动云盘 | B12: 会员用户数 | C12: 万户 | D12: 23484.974 | E12: -0.0030371084 | F12: -
B13: 全场景月活用户数 | C13: 万户 | D13: 17872.888 | E13: -0.064057313 | F13: 0.062539071
B14: 核心行为月活用户数 | C14: 万户 | D14: 10263.883 | E14: -0.080525712 | F14: -
A15: 咪咕音乐 | B15: 全场景月活用户数 | C15: 万户 | D15: 18517.158 | E15: -0.021068853 | F15: -0.10465375
A16: 云游戏 | B16: 全场景月活用户数 | C16: 万户 | D16: 11978.001 | E16: 0.021521742 | F16: 0.07889863
B17: 核心用户月活规模 | C17: 万户 | D17: 5218.8556 | E17: -0.033416686 | F17: -
B18: 会员用户数 | C18: 万户 | D18: 4768.371 | E18: -0.018574017 | F18: -0.027550583
A19: 移动认证 | B19: 月活用户数 | C19: 万户 | D19: 77637.473 | E19: -0.0016088612 | F19: 0.031449651
B20: 核心功能月活用户数 | C20: 万户 | D20: 36601.92 | E20: 0.0054305979 | F20: 0.12757261
A21: 和多号（含中间号） | B21: 月服务人次 | C21: 万人次 | D21: 44128.679 | E21: -0.1430403 | F21: 0.42830209
A22: 和包 | B22: 客户端月活用户数 | C22: 万户 | D22: 32758.137 | E22: -0.01130016 | F22: 0.48610686
B23: 客户端交易月活用户数 | C23: 万户 | D23: 8215.0394 | E23: -0.018532033 | F23: 0.21722328
A24: 139邮箱 | B24: 月活用户数 | C24: 万户 | D24: 21937.092 | E24: -0.0060277502 | F24: 0.11103921
A25: 和留言 | B25: 使用用户数 | C25: 万户 | D25: 16935.463 | E25: -0.0038628361 | F25: 0.013036832
A26: 5G新通话 | B26: 全场景月活用户数 | C26: 万户 | D26: 12184.09 | E26: -0.014492132 | F26: -
A27: 和彩印 | B27: 订购用户数 | C27: 万户 | D27: 10713.88 | E27: 0.010117314 | F27: 0.075686443
A28: 咪咕阅读 | B28: 全场景月活用户数 | C28: 万户 | D28: 10143.766 | E28: -0.0030033348 | F28: 0.035922428
A29: 5G消息 | B29: UP2.4终端在网用户到达数 | C29: 万户 | D29: 10767.889 | E29: 0.035816395 | F29: 4.7263329
A30: 云VR | B30: 全场景月活用户数 | C30: 万户 | D30: 758.3086 | E30: -0.16674631 | F30: -0.29789062
A31: 超级SIM | B31: 全场景月活用户数 | C31: 万户 | D31: 1707.0264 | E31: 0.0048281038 | F31: 1.9812941
A32: 二、H（家庭市场）
A33: 大屏点播 | B33: 到达用户数 | C33: 万户 | D33: 13056.834 | E33: 0.011993535 | F33: 0.14254148
B34: 其中：本年累计净增用户数 | C34: 万户 | D34: 323.2283 | E34: - | F34: -0.27837908
A35: 智能组网 | B35: 到达用户数 | C35: 万户 | D35: 14109.73 | E35: 0.018120466 | F35: 0.34111578
B36: 其中：本年累计净增用户数 | C36: 万户 | D36: 599.8418 | E36: - | F36: -0.056181158
A37: 家庭安防 | B37: 到达用户数 | C37: 万户 | D37: 5725.3337 | E37: 0.0074253744 | F37: 0.37520105
B38: 其中：本年累计净增用户数 | C38: 万户 | D38: 98.993 | E38: - | F38: -0.37580355
A39: 健康养老 | B39: 订购用户数 | C39: 万户 | D39: 4234.1579 | E39: 0.12393293 | F39: 1.9374956
B40: 其中：本年累计净增用户数 | C40: 万户 | D40: 200.3947 | E40: - | F40: 1.6233141
...

Sheet 主要产品效益情况表
A1: 主要产品效益情况表（7/17）
D2: =主要经营情况表!A2 -> 45323 | I2: 单位：亿元
A3: 产品名称 | B3: 本年累计
B4: 收入 | C4: 占通信服务收入比 | D4: 毛利 | E4: 占通信服务毛利比 | F4: 毛利率 | G4: 利润 | H4: 占通信服务利润比 | I4: 利润率
A5: 通信服务
A6: 一、C(个人市场）
A7: 其中:个人无线上网
A8: 个人语音
A9: 个人短彩信
A10: 权益产品
A11: 移动云盘
A12: 和留言
A13: 二、H（家庭市场）
A14: 其中:家庭宽带
A15: 移动高清
A16: 大屏点播
... A50: 主要通过综合权重分摊至各产品。利润率=利润/收入*100%
A51: 7

Sheet 个人市场
A1: 个人市场整体情况表（7/16）
A2: =主要经营情况表!A2 -> 45323
B3: 单位 | C3: 本月实际 | D3: 比上月± | E3: 比上年同期± | F3: 本年累计 | G3: 比上年同期±
A4: 一、收入规模
A5: 个人市场收入 | B5: 亿元 | C5: 430.86084 | D5: -0.0076985941 | E5: -0.021391716 | F5: 865.06444 | G5: -0.025469581
A6: 其中：个人市场增量收入 | B6: 亿元 | C6: -9.4183271 | D6: -0.28596752 | E6: - | F6: -22.608661 | G6: -4.5008241
A7: 二、客户发展
A8: 1.移动电话客户数 | B8: 万户 | C8: - | D8: - | E8: - | F8: 99106.556 | G8: 0.012688813
A9: 2.净增移动电话客户数 | B9: 万户 | C9: -51.0601 | D9: -1.8855484 | E9: -1.1626996 | F9: 6.5992 | G9: -0.98187754
A10: 移动电话客户离网率 | B10: % | C10: 0.012752216 | D10: -0.014648789 | E10: -0.041346734 | F10: 0.012827933 | G10: 0.0026943185
A11: 3.个人上网客户数 | B11: 万户 | C11: - | D11: - | E11: - | F11: 87367.508 | G11: 0.013768713
A12: 其中：手机上网客户数 | B12: 万户 | C12: - | D12: - | E12: - | F12: 87295.742 | G12: 0.013713727
A13: 4.有效融合客户数 | B13: 万户 | C13: - | D13: - | E13: - | F13: 49917.766 | G13: -
A14: 其中：“四大基座”融合客户数 | B14: 万户 | C14: - | D14: - | E14: - | F14: 28043.147 | G14: -
A15: “六大场景”融合客户数 | B15: 万户 | C15: - | D15: - | E15: - | F15: 46300.906 | G15: -
A16: 三、携号转网
A17: 1.携入至中国移动客户数 | B17: 万户 | C17: 70.4427 | D17: -0.20812106 | E17: -0.4185934 | F17: 159.3991 | G17: -0.26960987
A18: 其中：电信转移动 | B18: 万户 | C18: 40.4563 | D18: -0.21151342 | E18: -0.38905115 | F18: 91.7651 | G18: -0.23361692
A19: 联通转移动 | B19: 万户 | C19: 29.9864 | D19: -0.2034977 | E19: -0.45420029 | F19: 67.634 | G19: -0.31336319
A20: 2.从中国移动携出客户数 | B20: 万户 | C20: 81.9209 | D20: -0.26352644 | E20: -0.34721938 | F20: 193.1549 | G20: -0.20456772
A21: 其中：移动转电信 | B21: 万户 | C21: 49.9058 | D21: -0.26936614 | E21: -0.35919784 | F21: 118.2106 | G21: -0.22526663
A22: 移动转联通 | B22: 万户 | C22: 32.0151 | D22: -0.25423488 | E22: -0.32762716 | F22: 74.9443 | G22: -0.169572
A23: 3.净携入客户数
A24: 移动净携入客户数 | B24: 万户 | C24: -11.4782 | D24: - | E24: - | F24: -33.7558 | G24: -
A25: 电信净携入客户数 | B25: 万户 | C25: 12.0677 | D25: -0.435046 | E25: -0.39518158 | F25: 33.4282 | G25: -0.32705242
A26: 联通净携入客户数 | B26: 万户 | C26: -0.5895 | D26: -1.642787 | E26: - | F26: 0.3276 | G26: -
A27: 四、业务量
A28: 1.个人移动电话计费时长 | B28: 亿分钟 | C28: 1988.0075 | D28: -0.14210737 | E28: -0.11478397 | F28: 4305.3225 | G28: -0.067645192
A29: 2.个人上网流量 | B29: 亿MB | C29: 119266.06 | D29: -0.12526526 | E29: 0.0069696399 | F29: 255611.46 | G29: 0.057416682
A30: 其中：手机上网流量 | B30: 亿MB | C30: 119128.07 | D30: -0.12532187 | E30: 0.0071415762 | F30: 255324.53 | G30: 0.057741259
A31: 五、户均流量（DOU）
A32: 个人上网客户 | B32: GB/户·月 | C32: 14.020671 | D32: -0.064019942 | E32: -0.038330711 | F32: 14.516626 | G32: 0.02620869
A33: 其中：手机上网客户 | B33: GB/户·月 | C33: 14.015962 | D33: -0.064079449 | E33: -0.038114337 | F33: 14.512243 | G33: 0.026578421
A34: 六、户均收入及资费
A35: 1.个人客户出账ARPU | B35: 元/户·月 | C35: 62.507815 | D35: 0.050080785 | E35: -0.019601287 | F35: 60.967651 | G35: -0.0037295455
A36: 2.移动业务ARPU | B36: 元/户·月 | C36: 54.766599 | D36: 0.066711253 | E36: -0.04488964 | F36: 53.001829 | G36: -0.03174204
A37: 3.个人上网流量资费 | B37: 元/GB | C37: 2.9463465 | D37: 0.14782506 | E37: -0.040583035 | F37: 2.7439438 | G37: -0.093508927
A38: 其中：手机上网流量资费 | B38: 元/GB | C38: 2.9437904 | D38: 0.14778348 | E38: -0.041569624 | F38: 2.7416067 | G38: -0.094537107
A39: 4.每分钟语音业务收入 | B39: 元/分钟 | C39: 0.029430694 | D39: 0.074858272 | E39: 0.041170815 | F39: 0.028327415 | G39: 0.016191222
A40: 七、市场份额
...

Sheet 家庭市场
A1: 家庭市场整体情况表（8/16）
A2: =主要经营情况表!A2 -> 45323
B3: 单位 | C3: 本月实际 | D3: 比上月± | E3: 比上年同期± | F3: 本年累计 | G3: 比上年同期±
A4: 一、收入规模
A5: 家庭市场收入 | B5: 亿元 | C5: 115.81369 | D5: -0.0094863415 | E5: 0.075159274 | F5: 232.73656 | G5: 0.080947402
A6: 其中：家庭市场增量收入 | B6: 亿元 | C6: 8.0959848 | D6: -0.13250802 | E6: -0.34814089 | F6: 17.428618 | G6: -0.25603854
A7: 二、客户发展
A8: 1.家庭宽带客户数 | B8: 万户 | C8: - | D8: - | E8: - | F8: 26711.157 | G8: 0.076203392
A9: 其中：速率在(0,100M)家庭宽带客户数 | B9: 万户 | C9: - | D9: - | E9: - | F9: 756.1427 | G9: 0.03343417
A10: 速率在[100M,300M)家庭宽带客户数 | B10: 万户 | C10: - | D10: - | E10: - | F10: 8312.6877 | G10: -0.13890601
A11: 速率在[300M,500M)家庭宽带客户数 | B11: 万户 | C11: - | D11: - | E11: - | F11: 7176.1182 | G11: -0.065113864
A12: 速率在[500M,1000M)家庭宽带客户数 | B12: 万户 | C12: - | D12: - | E12: - | F12: 2104.2483 | G12: -0.076715373
A13: 千兆家庭宽带客户数 | B13: 万户 | C13: - | D13: - | E13: - | F13: 8361.9596 | G13: 0.86672926
A14: 千兆家庭宽带客户渗透率 | B14: % | C14: - | D14: - | E14: - | F14: 0.3130512 | G14: 13.257149
A15: 其中：0流量家庭宽带客户数 | B15: 万户 | C15: 4675.2941 | D15: 0.027086511 | E15: - | F15: - | G15: -
A16: 其中：0流量千兆家庭宽带客户数 | B16: 万户 | C16: 903.4231 | D16: 0.036901216 | E16: - | F16: - | G16: -
A17: 2.家庭宽带客户活跃率 | B17: % | C17: 0.82445529 | D17: -0.38114779 | E17: -1.7054364 | F17: - | G17: -
A18: 其中：千兆家庭宽带客户活跃率 | B18: % | C18: 0.89035726 | D18: -0.11659876 | E18: -1.3978904 | F18: - | G18: -
A19: 3.净增家庭宽带客户数 | B19: 万户 | C19: 125.9664 | D19: -0.38004451 | E19: -0.46359865 | F19: 329.1526 | G19: -0.26793142
A20: 其中：速率在(0,100M)家庭宽带客户数 | B20: 万户 | C20: 2.2724 | D20: -0.92678039 | E20: -0.49543709 | F20: 33.3078 | G20: -
A21: 速率在[100M,300M)家庭宽带客户数 | B21: 万户 | C21: -84.0823 | D21: - | E21: - | F21: -175.699 | G21: -
A22: 速率在[300M,500M)家庭宽带客户数 | B22: 万户 | C22: -8.0556 | D22: -1.2275002 | E22: - | F22: 27.3536 | G22: -0.39251346
A23: 速率在[500M,1000M)家庭宽带客户数 | B23: 万户 | C23: 7.9813 | D23: - | E23: - | F23: -5.1729 | G23: -
A24: 千兆家庭宽带客户数 | B24: 万户 | C24: 207.8506 | D24: -0.13937954 | E24: -0.45809737 | F24: 449.3631 | G24: -0.30437135
A25: 4.移动高清客户数 | B25: 万户 | C25: - | D25: - | E25: - | F25: 20968.545 | G25: 0.069170717
A26: 净增移动高清客户数 | B26: 万户 | C26: 72.5731 | D26: -0.51850719 | E26: -0.5205671 | F26: 223.2983 | G26: -0.37815073
A27: 移动高清客户渗透率 | B27: % | C27: - | D27: - | E27: - | F27: 0.78501075 | G27: -0.51635583
A28: 移动高清客户活跃率 | B28: % | C28: 0.57757348 | D28: 1.9199528 | E28: 0.30113536 | F28: - | G28: -
A29: 三、户均收入
A30: 1.家庭客户综合ARPU | B30: 元/户·月 | C30: 43.460275 | D30: -0.015603649 | E30: -0.0033463725 | F30: 43.814265 | G30: 0.00085963436
A31: 2.家庭宽带ARPU | B31: 元/户·月 | C31: 28.14668 | D31: -0.009549189 | E31: 0.0071869188 | F31: 28.288796 | G31: 0.0074738962
A32: 四、网络能力
A33: 家庭宽带端口数 | B33: 万个 | C33: - | D33: - | E33: - | F33: 47076.791 | G33: 0.066265605
A34: 家庭宽带端口实装率 | B34: % | C34: - | D34: - | E34: - | F34: 0.56739544 | G34: 0.52393955
A35: 五、市场份额
A36: 1.家庭宽带客户份额 | B36: % | C36: - | D36: - | E36: - | F36: 0.48455184 | G36: 0.32536135
A37: 家庭宽带客户净增份额 | B37: % | C37: 0.50806972 | D37: 58.58561 | E37: -9.4474063 | F37: 0.50806972 | G37: -9.4474063
A38: 2.移动高清客户份额 | B38: % | C38: - | D38: - | E38: - | F38: 0.51743887 | G38: 1.0165663
A39: 移动高清客户净增份额 | B39: % | C39: 0.53577847 | D39: -14.79817 | E39: -11.448825 | F39: 0.53577847 | G39: -11.448825
A40: 注：1.家庭宽带收入包含裸宽带、融合宽带、装移机收入、智能组网
...

Sheet 政企市场
A1: 政企市场整体情况表（9/16）
A2: =主要经营情况表!A2 -> 45323
A3: 指标 | B3: 单位 | C3: 本月实际 | D3: 比上月± | E3: 比上年同期± | F3: 本年累计 | G3: 比上年同期±
A4: 一、收入规模
A5: 政企市场收入 | B5: 亿元 | C5: 188.18417 | D5: -0.10391323 | E5: 0.076305685 | F5: 398.19082 | G5: 0.072843764
A6: 其中：政企市场增量收入 | B6: 亿元 | C6: 13.341491 | D6: -0.025798906 | E6: -0.43232353 | F6: 27.036292 | G6: -0.56737174
A7: 其中：专线业务收入 | B7: 亿元 | C7: 33.222869 | D7: -0.0032442885 | E7: 0.033708264 | F7: 66.553873 | G7: 0.026549739
A8: DICT业务收入 | B8: 亿元 | C8: 106.18986 | D8: -0.17882504 | E8: 0.078476027 | F8: 235.5044 | G8: 0.068604181
A9: 其中：行业云收入 | B9: 亿元 | C9: 63.404992 | D9: -0.19070301 | E9: 0.050326351 | F9: 141.75076 | G9: 0.092528939
A10: IDC业务收入 | B10: 亿元 | C10: 29.304354 | D10: 0.067907152 | E10: 0.089022649 | F10: 56.745273 | G10: 0.041271252
A11: ICT业务收入 | B11: 亿元 | C11: 22.690997 | D11: -0.32193021 | E11: 0.21399756 | F11: 56.155099 | G11: 0.098746852
A12: 应用及信息化业务收入 | B12: 亿元 | C12: 9.9171228 | D12: -0.069674505 | E12: 0.2414642 | F12: 20.576965 | G12: 0.25421524
A13: 物联网业务收入 | B13: 亿元 | C13: 20.876251 | D13: -0.21902232 | E13: 0.17832461 | F13: 47.60717 | G13: 0.21353504
A14: 其中：物联网流量收入 | B14: 亿元 | C14: 6.5401682 | D14: -0.039688324 | E14: 0.20801528 | F14: 13.350632 | G14: 0.25220315
A15: 物联网服务费收入 | B15: 亿元 | C15: 14.138978 | D15: -0.28414368 | E15: 0.1629365 | F15: 33.890118 | G15: 0.19786832
A16: 政企外部欠费原值 | B16: 亿元 | C16: - | D16: - | E16: - | F16: 705.41443 | G16: 0.41909694
A17: 二、业务发展
A18: 1.政企客户数 | B18: 万家 | C18: -33.109 | D18: - | E18: -3.9856709 | F18: 2779.3216 | G18: 0.21174131
A19: 2.政企成员数 | B19: 万户 | C19: -5.5889 | D19: - | E19: -1.0258948 | F19: 14526.877 | G19: 0.016708938
A20: 3.专线订购条数 | B20: 万条 | C20: 29.5518 | D20: -0.55692726 | E20: -0.54440648 | F20: 3958.1642 | G20: 0.18756934
A21: （1）互联网专线订购条数 | B21: 万条 | C21: 1.8427 | D21: -0.4980797 | E21: 0.34288005 | F21: 176.3126 | G21: 0.093507769
A22: （2）企业宽带订购条数 | B22: 万条 | C22: 23.5115 | D22: -0.56879571 | E22: -0.59630811 | F22: 3349.7899 | G22: 0.20363038
A23: （3）数据专线订购条数 | B23: 万条 | C23: 4.1975 | D23: -0.50622294 | E23: -0.20062845 | F23: 432.0612 | G23: 0.11158701
A24: 4.IDC外部客户已计费机架数 | B24: 万架 | C24: -0.2319 | D24: - | E24: - | F24: 16.6955 | G24: -
A25: IDC外部客户已计费机架总功率数 | B25: 万千瓦 | C25: -0.41453 | D25: - | E25: - | F25: 91.975058 | G25: -
A26: 5.IDC外部客户开通带宽量 | B26: 万Gbps | C26: 0.486185 | D26: - | E26: - | F26: 30.780166 | G26: -
A27: 其中：IDC外部客户计费带宽量 | B27: 万Gbps | C27: -0.772653 | D27: - | E27: - | F27: 15.735822 | G27: -
A28: 6.物联网卡客户数 | B28: 万户 | C28: -58.0275 | D28: - | E28: -1.0270899 | F28: 131391.07 | G28: 0.21615627
A29: 其中：NB-IoT客户数 | B29: 万户 | C29: -444.8255 | D29: - | E29: -2.1234755 | F29: 14887.254 | G29: 0.053143671
A30: 其中：车联网卡客户数 | B30: 万户 | C30: 108.9383 | D30: - | E30: - | F30: 22901.223 | G30: -
A31: 其中：前装车联网卡客户数 | B31: 万户 | C31: 5211.0377 | D31: 0.02935176 | E31: - | F31: 5211.0377 | G31: -
A32: 物联网流量 | B32: 亿MB | C32: 2648.766 | D32: -0.093270572 | E32: 1.3214601 | F32: 5569.9969 | G32: 1.4408183
A33: 三、户均收入
A34: 1.互联网专线ARPU | B34: 元/户·月 | C34: 658.55045 | D34: -0.027576271 | E34: -0.15068183 | F34: 668.39947 | G34: -0.15676149
A35: 2.企业宽带ARPU | B35: 元/户·月 | C35: 21.524756 | D35: 0.054036929 | E35: -0.081159574 | F35: 20.992598 | G35: -0.099208312
A36: 3.数据专线ARPU | B36: 元/户·月 | C36: 401.36301 | D36: -0.047078225 | E36: -0.066743812 | F36: 411.54956 | G36: -0.040310451
A37: 四、市场份额
A38: 1.政企市场收入份额 | B38: % | C38: - | D38: - | E38: - | F38: 0.40367639 | G38: -0.37351247
A39: 政企市场增量收入份额 | B39: % | C39: - | D39: - | E39: - | F39: 0.35678729 | G39: -34.821271
A40: 2.专线业务收入份额 | B40: % | C40: - | D40: - | E40: - | F40: 0.29690013 | G40: 1.7822262
...

Sheet 业务-能力投资
A1: 网络能力与投资情况表（10/16）
A2: =主要经营情况表!A2 -> 45323
A3: 指标名称 | B3: 单位 | C3: 本月净增 | D3: 本年累计净增 | E3: 到达数 | F3: 比上年同期±
A4: 一、通信能力
A5: 1.基站数 | B5: 万个 | C5: 1.8156 | D5: 5.5786 | E5: 667.1712 | F5: 0.098158941
A6: 其中：GSM基站数 | B6: 万个 | C6: -0.5181 | D6: -1.3285 | E6: 90.0401 | F6: -0.11914948
A7: 4G基站数 | B7: 万个 | C7: 0.7937 | D7: 0.7668 | E7: 337.7592 | F7: 0.010211003
A8: 其中：TD-LTE基站数 | B8: 万个 | C8: 0.6906 | D8: 0.3805 | E8: 218.7406 | F8: -0.0019938169
A9: LTE FDD基站数 | B9: 万个 | C9: 0.1031 | D9: 0.3863 | E9: 119.0186 | F9: 0.033438224
A10: 5G基站数 | B10: 万个 | C10: 1.5105 | D10: 5.9867 | E10: 200.5492 | F10: 0.51223897
A11: 其中：5G 700MHz基站数 | B11: 万个 | C11: 0.5874 | D11: 1.9613 | E11: 63.9137 | F11: 0.29476149
A12: 其中：开通轻量化（RedCap）功能5G基站数 | B12: 万个 | C12: -5.0336 | D12: - | E12: 14.1953 | F12: -
A13: NB-IoT基站数 | B13: 万个 | C13: 0.0295 | D13: 0.154 | E13: 38.8227 | F13: 0.012230925
A14: 2.载频数 | B14: 万个 | C14: 1.5585 | D14: 10.6135 | E14: 1885.6945 | F14: -0.0072653521
A15: 其中：GSM载频数 | B15: 万个 | C15: -1.5297 | D15: -5.6142 | E15: 299.7 | F15: -0.19532607
A16: 4G载频数 | B16: 万个 | C16: -0.523 | D16: 5.8994 | E16: 1015.2292 | F16: -0.035834911
A17: 其中：TD-LTE载频数 | B17: 万个 | C17: -0.684 | D17: 5.3817 | E17: 685.5425 | F17: -0.061029825
A18: LTE FDD载频数 | B18: 万个 | C18: 0.161 | D18: 0.5177 | E18: 329.6867 | F18: 0.021139398
A19: 5G载频数 | B19: 万个 | C19: 3.5599 | D19: 9.8713 | E19: 462.307 | F19: 0.26193297
A20: 其中：5G 700MHz载频 | B20: 万个 | C20: 1.5017 | D20: 4.2648 | E20: 185.407 | F20: 0.28302594
A21: NB-IoT载频数 | B21: 万个 | C21: 0.0513 | D21: 0.4604 | E21: 108.4583 | F21: 0.006738926
A22: 3.有线宽带端口数 | B22: 万个 | C22: 206.9113 | D22: 621.6178 | E22: 53673.118 | F22: 0.071641574
A23: 其中：家庭宽带端口数 | B23: 万个 | C23: 158.8879 | D23: 606.9811 | E23: 47076.791 | F23: 0.066265605
A24: 4.10G PON端口数 | B24: 万个 | C24: 10.6403 | D24: 31.5048 | E24: 775.5719 | F24: 0.62497384
... A28: 其中：租用铁塔公司的铁塔数 | B28: 万个 | C28: 0.15 | D28: 0.0542 | E28: 146.2709 | F28: 0.0089262558
A29: 二、资本开支
A30: 资本开支合计 | B30: 亿元 | C30: 39.959988 | D30: - | E30: 134.1946 | F30: -0.15211787
A31: 其中：连接 | B31: 亿元 | C31: 17.381591 | D31: - | E31: 82.873655 | F31: -
A32: 算力 | B32: 亿元 | C32: 11.334483 | D32: - | E32: 27.514411 | F32: -
A33: 能力 | B33: 亿元 | C33: 5.9397704 | D33: - | E33: 7.9706984 | F33: -
A34: 基础 | B34: 亿元 | C34: 5.5301776 | D34: - | E34: 16.486849 | F34: -
A35: 其中：移动通信网 | B35: 亿元 | C35: 13.525477 | D35: - | E35: 71.736476 | F35: -0.094847103
A36: 传输网 | B36: 亿元 | C36: 9.8387145 | D36: - | E36: 31.428097 | F36: -0.24476593
A37: 业务支撑网 | B37: 亿元 | C37: 11.950279 | D37: - | E37: 18.953977 | F37: -0.35531466
A38: 局房土建 | B38: 亿元 | C38: 2.6096729 | D38: - | E38: 8.0176729 | F38: 0.35736518
A39: 其他 | B39: 亿元 | C39: 2.0358449 | D39: - | E39: 4.0583779 | F39: 0.93619973
A40: 注：资本开支中连接主要包括5G、核心网、千兆家宽、集客专线、综合业务接入区、NB-IoT等；算力主要包括移动云、IT云、网络云、
A41: 数据承载网、省际传送网、数据中心等；能力主要包括智慧中台、自智网络、业务系统、支撑系统等；基础主要包括国际通信
A42: 设施、省内传送网、传输管道、汇聚机房、办公用房等。
A43: =政企市场!A54+1 -> 10

Sheet 财务-收入
A1: 营运收入情况表（11/16）
B2: =主要经营情况表!A2 -> 45323 | G2: 单位：亿元
A3: 指标 | B3: 单月 | C3: 比上月± | D3: 比上年同期± | E3: 本年累计 | F3: 上年同期 | G3: 比上年同期±
A4: 营运收入 | B4: 906.01272 | C4: -0.071866415 | D4: 0.027292438 | E4: 1882.179 | F4: 1823.3588 | G4: 0.032259278
A5: 一、通信服务收入 | B5: 776.99523 | C5: -0.032483166 | D5: 0.020870014 | E5: 1580.0771 | F5: 1548.1577 | G5: 0.020617651
A6: （一）语音业务收入 | B6: 59.046238 | C6: -0.078115975 | D6: -0.081759664 | E6: 123.09577 | F6: 130.36127 | G6: -0.055733619
A7: 1.移动语音通话收入 | B7: 55.231356 | C7: -0.06611554 | D7: -0.088748457 | E7: 114.37289 | F7: 122.64699 | G7: -0.067462789
A8: 2.语音增值业务收入 | B8: 1.5788566 | C8: 0.019215588 | D8: 0.038716491 | E8: 3.1279466 | F8: 2.9562264 | G8: 0.058087632
A9: 3.月租费收入 | B9: 1.7286223 | C9: -0.38219813 | D9: 0.24457597 | E9: 4.5266428 | F9: 3.1905438 | G9: 0.41876845
A10: 4.固定语音通话收入 | B10: 0.50740283 | C10: -0.095358926 | D10: -0.35306207 | E10: 1.0682914 | F10: 1.5675078 | G10: -0.3184778
A11: （二）数据业务收入 | B11: 693.35844 | C11: -0.036767898 | D11: 0.022695976 | E11: 1413.1833 | F11: 1381.4214 | G11: 0.022992224
A12: 1. 短彩信业务收入 | B12: 25.798936 | C12: -0.15034062 | D12: -0.056517341 | E12: 56.162793 | F12: 56.26067 | G12: -0.0017397185
A13: （1）短信业务收入 | B13: 25.503371 | C13: -0.15123819 | D13: -0.060497744 | E13: 55.551108 | F13: 55.833022 | G13: -0.0050492262
A14: 其中：点对点短消息收入 | B14: 2.6175535 | C14: 0.34444396 | D14: 0.35100217 | E14: 4.5644948 | F14: 3.9546045 | G14: 0.15422283
A15: 集团短信收入 | B15: 22.399943 | C15: -0.18860347 | D15: -0.092390809 | E15: 50.006598 | F15: 50.824363 | G15: -0.016090035
... A50: 其中：商品销售收入 | B50: 109.54985 | C50: -0.32198095 | D50: 0.011097856 | E50: 271.12325 | F50: 247.09566 | G50: 0.097240015
A51: ='业务-能力投资'!A43+1 -> 11

Sheet 财务-支出
A1: 营运支出情况表（12/16）
C2: =主要经营情况表!A2 -> 45323 | F2: 单位：亿元
A3: 指标 | B3: 单月 | C3: 比上月± | D3: 比上年同期± | E3: 本年累计 | F3: 上年同期 | G3: 比上年同期±
A4: 营运支出 | B4: 736.23642 | C4: -0.059298287 | D4: 0.075596822 | E4: 1518.8824 | F4: 1428.5927 | G4: 0.06320185
A5: 一、网络运营及支撑成本 | B5: 213.25316 | C5: -0.045629336 | D5: 0.022403368 | E5: 436.70215 | F5: 438.65921 | G5: -0.0044614652
A6: 1.维护支撑费用 | B6: 137.33796 | C6: -0.07211245 | D6: 0.054801257 | E6: 285.34939 | F6: 283.99022 | G6: 0.0047859924
A7: 2.能源使用费 | B7: 34.4874 | C7: -0.035831689 | D7: 0.022440319 | E7: 70.256465 | F7: 68.47035 | G7: 0.026085974
A8: 3.铁塔使用费 | B8: 21.160236 | C8: 0.062528604 | D8: -0.0052282572 | E8: 41.075216 | F8: 44.760773 | G8: -0.082338996
A9: 4.电路及网元使用费 | B9: 11.977713 | C9: 0.016396129 | D9: 0.29600362 | E9: 23.762207 | F9: 16.163665 | G9: 0.47010022
A10: 5.其他资产使用费 | B10: 2.9202502 | C10: 0.27825407 | D10: -0.53785572 | E10: 5.2048118 | F10: 11.570315 | G10: -0.55015816
A11: 6.其他 | B11: 5.3695987 | C11: -0.055389764 | D11: -0.31288413 | E11: 11.054058 | F11: 13.703894 | G11: -0.1933637
A12: 二、折旧及摊销 | B12: 176.39873 | C12: -0.0024893655 | D12: 0.013291268 | E12: 353.23768 | F12: 343.6143 | G12: 0.028006335
A13: 1.物业、厂房及设备折旧费 | B13: 146.96326 | C13: -0.0017533276 | D13: 0.015429623 | E13: 294.18464 | F13: 285.66472 | G13: 0.029824902
A14: 2.使用权资产折旧费 | B14: 24.940888 | C14: -0.0034736999 | D14: 0.021986143 | E14: 49.968716 | F14: 47.975002 | G14: 0.041557337
A15: 3.无形资产摊销 | B15: 4.4945866 | C15: -0.020731102 | D15: -0.092088118 | E15: 9.0843236 | F15: 9.9745821 | G15: -0.089252716
... A19: 2.业务宣传费 | B19: 1.0222251 | C19: -0.081029622 | D19: 0.29555611 | E19: 2.1345843 | F19: 1.6336244 | G19: 0.30665548
A20: 3.展览费 | B20: 0.10644755 | C20: - | D20: 1.6461758 | E20: 0.10604335 | F20: 0.039620803 | G20: 1.6764564
A21: 4.社会渠道相关费用 | B21: 21.878573 | C21: 0.035305733 | D21: -0.17218514 | E21: 43.011048 | F21: 54.093287 | G21: -0.20487272
A22: 其中：社会渠道服务费 | B22: 20.408959 | C22: 0.034914372 | D22: -0.17318193 | E22: 40.129392 | F22: 50.734686 | G22: -0.20903437
A23: 社会渠道手续费 | B23: 1.4696135 | C23: 0.040771443 | D23: -0.15808983 | E23: 2.881656 | F23: 3.3586014 | G23: -0.14200714
A24: 5.营销支撑费 | B24: 20.274268 | C24: 0.22059339 | D24: 2.1589812 | E24: 36.884442 | F24: 12.341901 | G24: 1.9885542
A25: 6.客户服务费 | B25: 3.1045372 | C25: -0.21870595 | D25: -0.16924726 | E25: 7.0781207 | F25: 7.2138363 | G25: -0.018813243
A26: 7.欠费催缴费 | B26: 0.013961902 | C26: 0.45245915 | D26: 0.27961068 | E26: 0.023574497 | F26: 0.021934055 | G26: 0.074789761
A27: 五、销售产品成本 | B27: 128.06869 | C27: -0.22091227 | D27: 0.063086109 | E27: 292.45157 | F27: 272.23711 | G27: 0.074253136
A28: 六、其他营运支出 | B28: 52.912002 | C28: -0.10300812 | D28: 0.31682639 | E28: 111.90028 | F28: 85.398131 | G28: 0.31033636
A29: 其中：坏账准备 | B29: 16.651384 | C29: -0.39537809 | D29: 0.22595435 | E29: 44.191543 | F29: 28.486931 | G29: 0.55129181
A30: 坏账率 | B30: 0.021430484 | C30: -1.2862607 | D30: 0.35850084 | E30: 0.027967967 | F30: 0.018400536 | G30: 0.95674309
A31: 1.网间互联支出 | B31: 15.335309 | C31: -0.11234919 | D31: -0.24339381 | E31: 32.611595 | F31: 33.744646 | G31: -0.033577197
A32: 2.呆账减值亏损 | B32: 16.66102 | C32: -0.39488996 | D32: 0.23214429 | E32: 44.194888 | F32: 28.425569 | G32: 0.55475822
... A36: 6.其他 | B36: 18.070382 | C36: 0.83073122 | D36: 4.3863264 | E36: 27.940963 | F36: 17.207442 | G36: 0.62377206
A37: 注：1.能源使用费是指动力水电取暖费等
A38: 2.坏账率=坏账准备/通信服务收入*100%
A39: ='财务-收入'!A51+1 -> 12

Sheet 市值管理
A1: 资本市场市值管理情况表（13/16）
A2: =主要经营情况表!A2 -> 45323
A3: 指标 | B3: 单位 | C3: 本月 | D3: 比上月± | F3: 比上年同期± | G3: 本月 | H3: 比上月± | J3: 比上年同期±
A4: 一、股价表现1 | C4: 港股（港元） | G4: A股（人民币）
A5: 1.中国移动股价-当期期末 | B5: 元/股 | C5: 65.8 | D5: -0.0097817908 | F5: 0.11904762 | G5: 102 | H5: -0.0041979889 | J5: 0.32069437
A6: -当期平均 | B6: 元/股 | C6: 66.816667 | D6: 0.01978332 | F6: 0.16461138 | G6: 103.134 | H6: 0.050020825 | J6: 0.38808499
A7: 2.中国电信股价-当期期末 | B7: 元/股 | C7: 4.17 | D7: 0.037313433 | F7: 0.066496164 | G7: 5.85 | H7: 0.017391304 | J7: 0.037638795
A8: -当期平均 | B8: 元/股 | C8: 4.1371429 | D8: 0.078146682 | F8: 0.05579759 | G8: 5.9046667 | H8: 0.095855126 | J8: 0.14489102
A9: 3.中国联通股价-当期期末 | B9: 元/股 | C9: 5.44 | D9: 0.014925373 | F9: -0.048951049 | G9: 4.8 | H9: 0.061946903 | J9: -0.065857076
A10: -当期平均 | B10: 元/股 | C10: 5.4347619 | D10: 0.09091936 | F10: -0.046951003 | G10: 4.6606667 | H10: 0.1094424 | J10: -0.065641024
A11: 4.三家股价平均变化-当期期末 | B11: % | C11: - | D11: 0.014152338 | F11: 0.045530911 | G11: - | H11: 0.025046739 | J11: 0.097492031
A12: -当期平均 | B12: % | C12: - | D12: 0.03736078 | F12: 0.057819324 | G12: - | H12: 0.085106117 | J12: 0.15577833
A13: 5.市场情况 | C13: 恒生指数 | G13: 上证指数
A14: 大盘指数-当期期末 | B14: 点 | C14: 16511.44 | D14: 0.066281263 | F14: -0.16549631 | G14: 3015.1712 | H14: 0.081269171 | J14: -0.080629855
A15: -当期平均 | B15: 点 | C15: 16140.913 | D15: 0.010589252 | F15: -0.22962262 | G15: 2895.4105 | H15: 0.0079122859 | J15: -0.11448873
A17: 指标 | B17: 单位 | C17: 本月 | F17: 比上月± | H17: 比上年同期±
A18: 二、市值规模与排名2
A19: 1.中国移动-市值 | B19: 亿元人民币 | C19: 13145.782 | F19: -0.0094913634 | H19: 0.12688585
A20: 全球运营商中市值排名 | B20: 位 | C20: 2 | F20: 持平 | H20: 持平
A21: 2.中国电信-市值 | B21: 亿元人民币 | C21: 5013.7302 | F21: 0.018229662 | H21: -0.027754568
A22: 全球运营商中市值排名 | B22: 位 | C22: 9 | F22: 持平 | H22: 下降2位
A23: 3.中国联通-市值 | B23: 亿元人民币 | C23: 1510.6181 | F23: 0.014925373 | H23: -0.048951049
A24: 全球运营商中市值排名 | B24: 位 | C24: 26 | F24: 持平 | H24: 上升2位
A26: 指标 | B26: 单位 | C26: 境外主要投行平均预测（港股) | G26: 境内主要投行平均预测（A股）
C27: 绝对值 | E27: 增幅 | G27: 绝对值 | I27: 增幅
A28: 三、资本市场对上市公司2023年业绩预期3
A29: 1.营运收入 | B29: 亿元人民币 | C29: 10105.26 | E29: 0.0782 | G29: 10231.448 | I29: 0.091635023
A30: 2.通信服务收入 | B30: 亿元人民币 | C30: 8717.27 | E30: 0.0735 | G30: - | I30: -
A31: 3.EBITDA | B31: 亿元人民币 | C31: 3504.75 | E31: 0.0647 | G31: - | I31: -
A32: 4.净利润 | B32: 亿元人民币 | C32: 1348.93 | E32: 0.0752 | G32: 1357.4558 | I32: 0.081991594
A33: 5.资本开支 | B33: 亿元人民币 | C33: 1831.06 | E33: -0.0027 | G33: 1832 | I33: -0.010799136
A34: 6.派息率 | B34: % | C34: 0.7055 | E34: 3.55pp | G34: - | I34: -
A35: 7.投资目标价 | B35: 元/股 | C35: 82.0港元 | G35: 111.5元人民币
A36: 注：1、当期期末为当期开市最后一天收盘价；当期平均为当期开市每天收盘价的平均值。
A37: 2、中国移动、中国电信市值按两地股数*股价折算为同一种货币后合计，中国联通按港股市值，排名按月末汇率折算美元后与国际运营商比较确定。
A38: 截至2月末，全球运营商按市值排名前五顺序为T-Mobile, 中国移动, Verizon, AT&T, 德国电信。
A39: 截至2月末，中国联通港股公司+A股公司市值合计为3,037亿人民币。
A40: 3、资本市场对上市公司2023年业绩预期为境内外主要投行对上市公司主要业绩指标全年表现及股票投资目标价的最新预测。
A41: ='财务-支出'!A39+1 -> 13

Sheet 信息服务业重点指标对标表
A1: 信息服务业重点指标对标表（14/16）
A2: =主要经营情况表!A2 -> 45323
A3: 国内信息服务业收入情况表 | E3: 国内信息服务业
A4: 指标 | D4: 单位 | E4: 本月 | F4: 比上月± | G4: 比上年同期± | H4: 本年累计 | I4: 比上年同期 ±
A5: 信息服务业收入 | D5: 亿元 | E5: 15878 | F5: 0.040157222 | G5: 0.087373912 | H5: 157541 | I5: 0.11824646
A6: 其中：通信业收入 | D6: 亿元 | E6: 1252 | F6: -0.092753623 | G6: -0.017865889 | H6: 16800 | I6: 0.062
A7: 软件及信息服务业收入 | D7: 亿元 | E7: 12811 | F7: 0.045283943 | G7: 0.092647915 | H7: 123258 | I7: 0.134
A8: 互联网和相关服务业收入 | D8: 亿元 | E8: 1815 | F8: 0.11418048 | G8: 0.1324997 | H8: 17483 | I8: 0.068
A9: 其中：通信业收入占信息服务业收入比 | D9: % | E9: 0.078851241 | F9: -1.1551642 | G9: -0.84492421 | H9: 0.10663891 | I9: -0.56478916
A10: 我公司收入占信息服务业收入比 | D10: % | E10: 0.038384658 | F10: -0.73890209 | G10: -0.76622028 | H10: 0.05506126 | I10: -0.28218048
A11: 注：1.该表取自工信部网站发布数据，因未公开1月数据，仍展示23年12月值。
A12: 2.从2022年开始规模以上互联网和相关服务企业口径由上年互联网和相关服务收入500万元以上调整为2000万元及以上
A13: 3.通信业收入为三家基础运营企业主营业务收入
A20: 国内外信息服务企业情况表
I21: 单位：人民币亿元
A22: 企业名称 | B22: 2023年1-3季度 营运收入 | D22: 2023年1-3季度 净利润 | F22: 2022年 营运收入 | H22: 2022年 净利润
B23: 本年累计 | C23: 同比增幅 | D23: 本年累计 | E23: 同比增幅 | F23: 本年累计 | G23: 同比增幅 | H23: 本年累计 | I23: 同比增幅
A24: 一、国际运营商
A25: 中国移动 | B25: 7755.6 | C25: 0.072 | D25: 1056.11 | E25: 0.071 | F25: 9372.59 | G25: 0.10492209 | H25: 1255.94 | I25: 0.079858305
A26: Verizon | B26: 6933.74 | C26: -0.027 | D26: 1028.94 | E26: -0.025 | F26: 9203.6261 | G26: 0.02411442 | H26: 1462.787 | I26: -0.038464939
A27: Comcast | B27: 6335.72 | C27: -0.006 | D27: 838.48 | E27: 4.825 | F27: 8167.2723 | G27: 0.043321734 | H27: 331.25924 | I27: -0.64396732
A28: AT&T | B28: 6341.83 | C28: 0.011 | D28: 914.8 | E28: -0.19 | F28: 8121.1315 | G28: -0.099203211 | H28: -474.52466 | I28: -1.3284604
A29: Deutsche Telekom | B29: 6292.72 | C29: -0.024 | D29: 1433.72 | E29: 1.694 | F29: 8091.3701 | G29: 0.061236794 | H29: 565.83651 | I29: 0.91594828
A30: NTT | B30: 5057.35 | C30: 0.043 | D30: 436.28 | E30: 0.011 | F30: 6733.7491 | G30: 0.08059952 | H30: 662.67981 | I30: 0.029269248
A31: 中国电信 | B31: 3842.56 | C31: 0.064 | D31: 271.43 | E31: 0.102 | F31: 4814.48 | G31: 0.095312738 | H31: 276.76 | I31: 0.058396115
A32: 中国联通 | B32: 2816.91 | C32: 0.067 | D32: 173.77 | E32: 0.105 | F32: 3549.44 | G32: 0.082628243 | H32: 168.37 | I32: 0.16061212
A33: Vodafone | B33: 2519.27 | C33: -0.037 | D33: - | E33: - | F33: 3232.3614 | G33: 0.0027643703 | H33: 872.34012 | I33: 3.448251
A34: Orange | B34: 2478.9 | C34: 0.013 | D34: - | E34: - | F34: 3074.2776 | G34: 0.02231022 | H34: 185.07613 | I34: 2.3637532
A35: KDDI | B35: 2174 | C35: 0.022550888 | D35: 261.94636 | E35: 0.087992231 | F35: 2907.4026 | G35: 0.04131927 | H35: 378.50824 | I35: 0.0079913725
A36: Telefonica | B36: 2323.063 | C36: 0.023711367 | D36: 96.155185 | E36: -0.15042822 | F36: 2828.3339 | G36: 0.018229498 | H36: 142.21937 | I36: -0.75285732
A37: BT | B37: 1363.3915 | C37: 0.015 | D37: - | E37: - | F37: 1462.5753 | G37: -0.0059601057 | H37: 134.72298 | I37: 0.49529042
A38: SK Telecom | B38: 706.73 | C38: 0.013 | D38: 51.78 | E38: 0.324 | F38: 902.16063 | G38: 0.03322 | H38: 49.413299 | I38: -0.6081706
A39: LG U+ | B39: 570.0706 | C39: 0.024901405 | D39: 28.3686 | E39: 0.043514763 | F39: 724.96137 | G39: 0.0039607044 | H39: 34.542759 | I39: -0.085087508
A40: 二、软件和互联网企业
A41: Amazon | B41: 28397.71 | C41: 0.11 | D41: 1389.01 | E41: - | F41: 34570.887 | G41: 0.093995173 | H41: -183.08379 | I41: -1.0815849
A42: Google | B42: 15508.67 | C42: 0.069 | D42: 3725.44 | E42: 0.146 | F42: 19023.764 | G42: 0.097808156 | H42: 4033.7623 | I42: -0.21089474
A43: 阿里巴巴集团 | B43: 6671.46 | C43: 0.082 | D43: 816.92 | E43: - | F43: 8686.87 | G43: 0.018316371 | H43: 655.73 | I43: 0.39282907
A44: 腾讯 | B44: 4538.19 | C44: 0.108 | D44: 901.98 | E44: 0.103 | F44: 5545.52 | G44: -0.0099371918 | H44: 1887.09 | I44: -0.17163865
A45: 注：1.根据2022年《财富》世界500强排名对运营商部分进行更新，补充了排名更高的 Vodafone（沃达丰）
A46: 和 Orange（法国电信），用以替换 BT（英国电信）和 Telefonica（西班牙电信）
...

Sheet 电信行业主要指标情况表
A1: 电信行业主要指标情况表（15/16）
A2: =主要经营情况表!A2 -> 45323
A3: 指标 | C3: 单位 | D3: 行业 | E3: 移动 | F3: 电信 | G3: 联通
A4: 一、经济效益
A5: （一）通信服务收入 | B5: 本年累计 | C5: 亿元 | D5: 1461.3438 | E5: 728.17964 | F5: 427.94273 | G5: 305.22141
B6: 同比变化 | C6: % | D6: 0.0426 | E6: 0.0285 | F6: 0.0556 | G6: 0.0589
A7: 其中：移动数据流量收入 | B7: 本年累计 | C7: 亿元 | D7: 517.82553 | E7: 309.11451 | F7: 124.39999 | G7: 84.311022
B8: 同比变化 | C8: % | D8: -0.0336 | E8: -0.043 | F8: -0.0123 | G8: -0.0295
B9: 市场份额 | C9: % | D9: - | E9: 0.59694723 | F9: 0.24023534 | G9: 0.16281743
B10: 市场份额同比变化 | C10: PP | D10: - | E10: -0.58634315 | F10: 0.51807357 | G10: 0.068784283
B11: 市场份额比年末变化 | C11: PP | D11: - | E11: -1.2254181 | F11: 1.0555255 | G11: 0.16989268
A12: 有线宽带收入 | B12: 本年累计 | C12: 亿元 | D12: 217.31769 | E12: 93.58478 | F12: 84.635519 | G12: 39.097391
B13: 同比变化 | C13: % | D13: 0.0559 | E13: 0.0836 | F13: 0.043 | G13: 0.021
B14: 市场份额 | C14: % | D14: - | E14: 0.43063581 | F14: 0.38945527 | G14: 0.17990892
B15: 市场份额同比变化 | C15: PP | D15: - | E15: 1.1008317 | F15: -0.48168485 | G15: -0.61496781
B16: 市场份额比年末变化 | C16: PP | D16: - | E16: -2.177645 | F16: 1.7342649 | G16: 0.44338005
A17: IPTV（互联网电视）收入 | B17: 本年累计 | C17: 亿元 | D17: 35.740584 | E17: 23.505706 | F17: 7.917528 | G17: 4.31735
B18: 同比变化 | C18: % | D18: 0.0365 | E18: 0.0598 | F18: -0.0383 | G18: 0.0603
B19: 市场份额 | C19: % | D19: - | E19: 0.65767549 | F19: 0.22152766 | G19: 0.12079685
B20: 市场份额同比变化 | C20: PP | D20: - | E20: 1.445918 | F20: -1.7230185 | G20: 0.27114638
B21: 市场份额比年末变化 | C21: PP | D21: - | E21: -0.38559741 | F21: -0.56421068 | G21: 0.94980808
A22: 政企信息化收入 | B22: 本年累计 | C22: 亿元 | D22: 332.7373 | E22: 107.5415 | F22: 139.8233 | G22: 85.372497
B23: 同比变化 | C23: % | D23: 0.1460224 | E23: 0.077407114 | F23: 0.20042573 | G23: 0.15293254
B24: 市场份额 | C24: % | D24: - | E24: 0.32320243 | F24: 0.4202213 | G24: 0.25657627
B25: 市场份额同比变化 | C25: PP | D25: - | E25: -2.0583331 | F25: 1.904444 | G25: 0.1537798
B26: 市场份额比年末变化 | C26: PP | D26: - | E26: -1.414969 | F26: 2.0768884 | G26: -0.66191942
A27: 物联网业务收入 | B27: 本年累计 | C27: 亿元 | D27: 27.548146 | E27: 12.88741 | F27: 3.989876 | G27: 10.67086
B28: 同比变化 | C28: % | D28: 0.1679 | E28: 0.2282 | F28: -0.019 | G28: 0.1819
B29: 市场份额 | C29: % | D29: - | E29: 0.46781406 | F29: 0.14483283 | G29: 0.38735311
B30: 市场份额同比变化 | C30: PP | D30: - | E30: 2.2967911 | F30: -2.7593533 | G30: 0.45883269
B31: 市场份额比年末变化 | C31: PP | D31: - | E31: -0.54962575 | F31: 0.35277178 | G31: 0.19685397
A32: （二）利润总额 | B32: 本年累计 | C32: 亿元 | D32: 156.23536 | E32: 93.273023 | F32: 47.110254 | G32: 15.852079
B33: 同比变化 | C33: % | D33: 0.0384 | E33: 0.0177 | F33: 0.0587 | G33: 0.1073
B34: 市场份额 | C34: % | D34: - | E34: 0.5970033 | F34: 0.30153389 | G34: 0.10146281
B35: 市场份额同比变化 | C35: PP | D35: - | E35: -1.2143037 | F35: 0.57817492 | G35: 0.6313364
B36: 市场份额比年末变化 | C36: PP | D36: - | E36: -16.418503 | F36: 14.95781 | G36: 1.4606933
A37: 注：1.本表数据为三家运营商报工信部的集团公司数据，源于工信部反馈，为上月值
A38: 2.IPTV（互联网电视）收入=移动高清业务收入+大屏点播业务收入
A39: 3.政企信息化收入=数据中心业务收入+云计算业务收入+大数据业务收入+集成业务收入
A40: =信息服务业重点指标对标表!A52+1 -> 15
...

Sheet 电信行业主要指标情况表（续）
A1: 电信行业主要指标情况表（续）（16/16）
A2: =主要经营情况表!A2 -> 45323
A3: 指标 | C3: 单位 | D3: 行业 | E3: 移动 | F3: 电信 | G3: 联通
A4: 二、用户情况
A5: （一）移动电话客户数 | B5: 本期到达 | C5: 万户 | D5: 172938.93 | E5: 98613.81 | F5: 40904.97 | G5: 33420.16
B6: 同比变化 | C6: % | D6: 0.0257 | E6: 0.0164 | F6: 0.0427 | G6: 0.0331
B7: 市场份额 | C7: % | D7: - | E7: 0.57022332 | F7: 0.23652841 | G7: 0.19324833
B8: 市场份额比年末变化 | C8: PP | D8: - | E8: -0.056881829 | F8: 0.035805902 | G8: 0.021081709
B9: 年累计净增 | C9: 万户 | D9: 279.29 | E9: 61.04 | F9: 127.88 | G9: 90.37
A10: 其中：5G网络客户数 | B10: 本期到达 | C10: 万户 | D10: 81662.27 | E10: 46411.54 | F10: 20113.84 | G10: 15136.9
B11: 同比变化 | C11: % | D11: 0.4214 | E11: 0.3853 | F11: 0.4977 | G11: 0.4389
B12: 市场份额 | C12: % | D12: - | E12: 0.56833517 | F12: 0.24630518 | G12: 0.18535978
B13: 市场份额比年末变化 | C13: PP | D13: - | E13: -0.62341738 | F13: 0.36864095 | G13: 0.25478867
B14: 年累计净增 | C14: 万户 | D14: 1163.84 | E14: 159.6 | F14: 583.41 | G14: 420.83
A15: （二）有线宽带客户数 | B15: 本期到达 | C15: 万户 | D15: 64110.96 | E15: 30072.37 | F15: 22616.29 | G15: 11422.3
B16: 同比变化 | C16: % | D16: 0.0797 | E16: 0.0952 | F16: 0.0514 | G16: 0.0973
B17: 市场份额 | C17: % | D17: - | E17: 0.46906754 | F17: 0.35276792 | G17: 0.17816454
B18: 市场份额比年末变化 | C18: PP | D18: - | E18: 0.056431118 | F18: -0.048689574 | G18: -0.0077258285
B19: 年累计净增 | C19: 万户 | D19: 480.33 | E19: 261.21 | F19: 138.46 | G19: 80.66
A20: 其中：千兆有线宽带客户数 | B20: 本期到达 | C20: 万户 | D20: 16840.05 | E20: 8528.31 | F20: 5748.53 | G20: 2563.2
B21: 同比变化 | C21: % | D21: 0.7505 | E21: 1.0189 | F21: 0.5454 | G21: 0.529
B22: 市场份额 | C22: % | D22: - | E22: 0.50643021 | F22: 0.34136063 | G22: 0.15220857
B23: 市场份额比年末变化 | C23: PP | D23: - | E23: -0.029586084 | F23: 0.0029547577 | G23: 0.026571944
B24: 年累计净增 | C24: 万户 | D24: 512.52 | E24: 254.73 | F24: 175.44 | G24: 82.35
A25: （三）IPTV（互联网电视） 客户数 | B25: 本期到达 | C25: 万户 | D25: 40383.46 | E25: 20895.97 | F25: 14711.06 | G25: 4776.43
B26: 同比变化 | C26: % | D26: 0.0527 | E26: 0.0738 | F26: 0.0115 | G26: 0.096
B27: 市场份额 | C27: % | D27: - | E27: 0.51743882 | F27: 0.36428429 | G27: 0.11827689
B28: 市场份额比年末变化 | C28: PP | D28: - | E28: 0.012852457 | F28: -0.091268087 | G28: 0.078390694
B29: 年累计净增 | C29: 万户 | D29: 281.32 | E29: 150.73 | F29: 65.88 | G29: 64.71
A30: （四）物联网卡客户数 | B30: 本期到达 | C30: 万户 | D30: 235261.27 | E30: 131449.09 | F30: 53243.83 | G30: 50568.34
B31: 同比变化 | C31: % | D31: 0.2647 | E31: 0.2413 | F31: 0.3119 | G31: 0.2789
B32: 市场份额 | C32: % | D32: - | E32: 0.55873663 | F32: 0.22631787 | G32: 0.21494545
B33: 市场份额比年末变化 | C33: PP | D33: - | E33: -0.54488677 | F33: 0.22770409 | G33: 0.31717843
B34: 年累计净增 | C34: 万户 | D34: 2035.38 | E34: -133.57 | F34: 991.71 | G34: 1177.24
A35: 三、业务量情况
A36: 个人上网流量 | B36: 本年累计 | C36: 万GB | D36: 2577196.3 | E36: 1325208.4 | F36: 734456.29 | G36: 517531.6
B37: 同比变化 | C37: % | D37: 0.213 | E37: 0.1048 | F37: 0.4052 | G37: 0.2859
B38: 市场份额 | C38: % | D38: - | E38: 0.51420546 | F38: 0.28498267 | G38: 0.20081187
B39: 市场份额同比变化 | C39: PP | D39: - | E39: -5.0359369 | F39: 3.8979269 | G39: 1.1384388
B40: 市场份额比年末变化 | C40: PP | D40: - | E40: -3.4711705 | F40: 2.7097283 | G40: 0.76144214
...

Sheet 分省财务-收入和利润
A1: 收入和利润情况表（1/36)
D2: =主要经营情况表!A2 -> 45323 | K2: 单位：亿元
A3: 单位 | B3: 营运收入 | D3: 通信服务收入 | F3: 通信服务收入 （含双计双考） | H3: 归属于母公司所有者的净利润 | J3: 净利润率
B4: 本年累计 | C4: 比上年 同期± | D4: 本年累计 | E4: 比上年 同期± | F4: 本年累计 | G4: 比上年 同期± | H4: 本年累计 | I4: 比上年 同期± | J4: 本年累计 | K4: 比上年同期±
A5: 广东 | B5: 216.26299 | C5: 0.032611126 | D5: 213.50609 | E5: 0.030334761 | F5: 1135.8015 | G5: 0.079607648 | H5: 44.739991 | I5: -0.12184242 | J5: 0.20687771 | K5: -3.6386402
A6: 江苏 | B6: 147.85293 | C6: 0.032869139 | D6: 139.79828 | E6: 0.035473575 | F6: 1135.8015 | G6: 0.079607648 | H6: 32.639201 | I6: -0.099772306 | J6: 0.22075452 | K6: -3.2526435
A7: 浙江 | B7: 144.72396 | C7: 0.033738817 | D7: 136.92939 | E7: 0.036330815 | F7: 1135.8015 | G7: 0.079607648 | H7: 36.552899 | I7: -0.040186466 | J7: 0.25256979 | K7: -1.9453042
A8: 山东 | B8: 101.84733 | C8: 0.059219465 | D8: 97.739168 | E8: 0.052959252 | F8: 1135.8015 | G8: 0.079607648 | H8: 18.554785 | I8: 0.00060772708 | J8: 0.18218235 | K8: -1.0671539
A9: 河南 | B9: 88.945351 | C9: 0.00024455092 | D9: 87.235711 | E9: 0.0050350576 | F9: 1135.8015 | G9: 0.079607648 | H9: 20.171349 | I9: -0.06517295 | J9: 0.22678362 | K9: -1.5869907
A10: 四川 | B10: 75.027554 | C10: 0.039262922 | D10: 73.091028 | E10: 0.021647795 | F10: 1135.8015 | G10: 0.079607648 | H10: 12.098455 | I10: 0.055043092 | J10: 0.1612535 | K10: 0.24118517
A11: 云南 | B11: 66.343865 | C11: 0.043282525 | D11: 65.849375 | E11: 0.04500877 | F11: 1135.8015 | G11: 0.079607648 | H11: 20.039229 | I11: 0.039962755 | J11: 0.30205098 | K11: -0.096420739
A12: 福建 | B12: 55.614444 | C12: 0.0033290053 | D12: 52.345707 | E12: 0.0017992064 | F12: 1135.8015 | G12: 0.079607648 | H12: 8.4313153 | I12: -0.22504275 | J12: 0.15160298 | K12: -4.4675804
